Workbook
Name Efficiency: Parametrar!$B$4

Sheet Parametrar
A1: BATTERI-ARBITRAGE BERÄKNING
A3: REDIGERBARA PARAMETRAR
A4: Round-trip effektivitet | B4: 0.88 | C4: (Ändra för att uppdatera alla revenue-beräkningar)
A6: FASTA PARAMETRAR
A7: Zoner | B7: SE1, SE2, SE3, SE4
A9: FORMELFÖRKLARING
A10: Spread | B10: =Max pris - Min pris
A11: 1-Cycle Revenue | B11: =MAX(0, Max pris × effektivitet - Min pris)
A12: 2-Cycle Revenue | B12: =(Morgonpris × eff - Nattpris) + (Kvällspris × eff - Middagspris)
A14: TIDSZONER FÖR 2-CYCLE
A15: Cycle 1: Ladda | B15: 00:00-06:00 (natt)
A16: Cycle 1: Ladda ur | B16: 07:00-10:00 (morgon)
A17: Cycle 2: Ladda | B17: 11:00-15:00 (middag)
A18: Cycle 2: Ladda ur | B18: 17:00-21:00 (kväll)
A20: SHEET-STRUKTUR
A21: Priser SEn | B21: Dagliga min/max/avg priser per zon
A22: Beräkningar | B22: Revenue-formler per dag (refererar till Efficiency)
A23: Månadssammanfattning | B23: Aggregerat per månad och zon
A24: Årssammanfattning | B24: Aggregerat per år och zon
A25: Zonöversikt | B25: Pivot-vy: År × Zon för snabb jämförelse

Sheet Priser SE1
A1: Datum | B1: Min EUR/MWh | C1: Max EUR/MWh | D1: Min timme | E1: Max timme | F1: Avg EUR/MWh | G1: Period | H1: År | I1: Natt avg | J1: Morgon avg | K1: Middag avg | L1: Kväll avg
A2: 2021-11-01 | B2: 10.75 | C2: 19.97 | D2: 23:00 | E2: 06:00 | F2: 14.66 | G2: 2021-11 | H2: 2021 | I2: 15.05 | J2: 17.36 | K2: 14.46 | L2: 13.5
A3: 2021-11-02 | B3: 3.43 | C3: 18.7 | D3: 03:00 | E3: 12:00 | F3: 14.66 | G3: 2021-11 | H3: 2021 | I3: 7.65 | J3: 17.07 | K3: 18.32 | L3: 17.54
A4: 2021-11-03 | B4: 14.96 | C4: 22.98 | D4: 02:00 | E4: 21:00 | F4: 20.06 | G4: 2021-11 | H4: 2021 | I4: 16.44 | J4: 20.88 | K4: 21.31 | L4: 22.59
A5: 2021-11-04 | B5: 18.02 | C5: 34.38 | D5: 02:00 | E5: 09:00 | F5: 24.98 | G5: 2021-11 | H5: 2021 | I5: 20 | J5: 31.96 | K5: 29.23 | L5: 23.74
A6: 2021-11-05 | B6: 7.33 | C6: 20.19 | D6: 23:00 | E6: 06:00 | F6: 16.64 | G6: 2021-11 | H6: 2021 | I6: 16.42 | J6: 19.84 | K6: 18.41 | L6: 15.26
A7: 2021-11-06 | B7: 1.82 | C7: 13.95 | D7: 02:00 | E7: 18:00 | F7: 8.79 | G7: 2021-11 | H7: 2021 | I7: 2.55 | J7: 7.31 | K7: 12.26 | L7: 13.33
A8: 2021-11-07 | B8: 1.47 | C8: 18.02 | D8: 04:00 | E8: 17:00 | F8: 11.81 | G8: 2021-11 | H8: 2021 | I8: 3.43 | J8: 11.71 | K8: 15.31 | L8: 17.57
A9: 2021-11-08 | B9: 15.22 | C9: 29.37 | D9: 01:00 | E9: 12:00 | F9: 21.3 | G9: 2021-11 | H9: 2021 | I9: 17.13 | J9: 24.24 | K9: 25.49 | L9: 21.55
A10: 2021-11-09 | B10: 6.48 | C10: 17.02 | D10: 23:00 | E10: 00:00 | F10: 13.14 | G10: 2021-11 | H10: 2021 | I10: 14.13 | J10: 12.11 | K10: 12.73 | L10: 14.3
A11: 2021-11-10 | B11: 3.55 | C11: 12.66 | D11: 23:00 | E11: 07:00 | F11: 9.45 | G11: 2021-11 | H11: 2021 | I11: 6.04 | J11: 12.43 | K11: 12.22 | L11: 10.69
A12: 2021-11-11 | B12: 2.93 | C12: 12.93 | D12: 00:00 | E12: 18:00 | F12: 10.39 | G12: 2021-11 | H12: 2021 | I12: 5.35 | J12: 12.31 | K12: 12.7 | L12: 12.78
A13: 2021-11-12 | B13: 11.01 | C13: 16.43 | D13: 00:00 | E13: 14:00 | F13: 14.28 | G13: 2021-11 | H13: 2021 | I13: 11.9 | J13: 13.98 | K13: 15.85 | L13: 15.65
... A1528: 2026-01-05 | B1528: 79.93 | C1528: 250.58 | D1528: 05:00 | E1528: 17:00 | F1528: 138.93 | G1528: 2026-01 | H1528: 2026 | I1528: 87.65 | J1528: 144.6 | K1528: 155.8 | L1528: 181.19

Sheet Priser SE2
A1: Datum | B1: Min EUR/MWh | C1: Max EUR/MWh | D1: Min timme | E1: Max timme | F1: Avg EUR/MWh | G1: Period | H1: År | I1: Natt avg | J1: Morgon avg | K1: Middag avg | L1: Kväll avg
A2: 2021-11-01 | B2: 10.75 | C2: 19.97 | D2: 23:00 | E2: 06:00 | F2: 14.66 | G2: 2021-11 | H2: 2021 | I2: 15.05 | J2: 17.36 | K2: 14.46 | L2: 13.5
A3: 2021-11-02 | B3: 3.43 | C3: 18.7 | D3: 03:00 | E3: 12:00 | F3: 14.66 | G3: 2021-11 | H3: 2021 | I3: 7.65 | J3: 17.07 | K3: 18.32 | L3: 17.54
A4: 2021-11-03 | B4: 14.96 | C4: 22.98 | D4: 02:00 | E4: 21:00 | F4: 20.06 | G4: 2021-11 | H4: 2021 | I4: 16.44 | J4: 20.88 | K4: 21.31 | L4: 22.59
A5: 2021-11-04 | B5: 18.02 | C5: 34.38 | D5: 02:00 | E5: 09:00 | F5: 24.98 | G5: 2021-11 | H5: 2021 | I5: 20 | J5: 31.96 | K5: 29.23 | L5: 23.74
A6: 2021-11-05 | B6: 7.33 | C6: 20.19 | D6: 23:00 | E6: 06:00 | F6: 16.64 | G6: 2021-11 | H6: 2021 | I6: 16.42 | J6: 19.84 | K6: 18.41 | L6: 15.26
A7: 2021-11-06 | B7: 1.82 | C7: 13.95 | D7: 02:00 | E7: 18:00 | F7: 8.79 | G7: 2021-11 | H7: 2021 | I7: 2.55 | J7: 7.31 | K7: 12.26 | L7: 13.33
A8: 2021-11-07 | B8: 1.47 | C8: 18.02 | D8: 04:00 | E8: 17:00 | F8: 11.81 | G8: 2021-11 | H8: 2021 | I8: 3.43 | J8: 11.71 | K8: 15.31 | L8: 17.57
A9: 2021-11-08 | B9: 15.22 | C9: 29.37 | D9: 01:00 | E9: 12:00 | F9: 21.3 | G9: 2021-11 | H9: 2021 | I9: 17.13 | J9: 24.24 | K9: 25.49 | L9: 21.55
A10: 2021-11-09 | B10: 6.48 | C10: 17.02 | D10: 23:00 | E10: 00:00 | F10: 13.14 | G10: 2021-11 | H10: 2021 | I10: 14.13 | J10: 12.11 | K10: 12.73 | L10: 14.3
A11: 2021-11-10 | B11: 3.55 | C11: 12.66 | D11: 23:00 | E11: 07:00 | F11: 9.45 | G11: 2021-11 | H11: 2021 | I11: 6.04 | J11: 12.43 | K11: 12.22 | L11: 10.69
A12: 2021-11-11 | B12: 2.93 | C12: 12.93 | D12: 00:00 | E12: 18:00 | F12: 10.39 | G12: 2021-11 | H12: 2021 | I12: 5.35 | J12: 12.31 | K12: 12.7 | L12: 12.78
A13: 2021-11-12 | B13: 11.01 | C13: 16.43 | D13: 00:00 | E13: 14:00 | F13: 14.28 | G13: 2021-11 | H13: 2021 | I13: 11.9 | J13: 13.98 | K13: 15.85 | L13: 15.65
... A1528: 2026-01-05 | B1528: 81.08 | C1528: 250.58 | D1528: 05:00 | E1528: 17:00 | F1528: 139.05 | G1528: 2026-01 | H1528: 2026 | I1528: 87.97 | J1528: 144.61 | K1528: 155.86 | L1528: 181.19

Sheet Priser SE3
A1: Datum | B1: Min EUR/MWh | C1: Max EUR/MWh | D1: Min timme | E1: Max timme | F1: Avg EUR/MWh | G1: Period | H1: År | I1: Natt avg | J1: Morgon avg | K1: Middag avg | L1: Kväll avg
A2: 2021-11-01 | B2: 10.75 | C2: 91.13 | D2: 23:00 | E2: 17:00 | F2: 51.12 | G2: 2021-11 | H2: 2021 | I2: 15.05 | J2: 81.21 | K2: 78.68 | L2: 58.99
A3: 2021-11-02 | B3: 3.43 | C3: 99.13 | D3: 03:00 | E3: 16:00 | F3: 65.29 | G3: 2021-11 | H3: 2021 | I3: 18.07 | J3: 92.78 | K3: 95.89 | L3: 91.32
A4: 2021-11-03 | B4: 14.96 | C4: 119.41 | D4: 02:00 | E4: 17:00 | F4: 72.24 | G4: 2021-11 | H4: 2021 | I4: 25.15 | J4: 101.19 | K4: 100.56 | L4: 100.07
A5: 2021-11-04 | B5: 18.02 | C5: 124.83 | D5: 02:00 | E5: 16:00 | F5: 80.3 | G5: 2021-11 | H5: 2021 | I5: 33.38 | J5: 122.11 | K5: 112.17 | L5: 84.05
A6: 2021-11-05 | B6: 7.33 | C6: 102.41 | D6: 23:00 | E6: 08:00 | F6: 56.8 | G6: 2021-11 | H6: 2021 | I6: 24.01 | J6: 100.1 | K6: 86.9 | L6: 50.53
A7: 2021-11-06 | B7: 1.82 | C7: 75.09 | D7: 02:00 | E7: 16:00 | F7: 14.32 | G7: 2021-11 | H7: 2021 | I7: 2.55 | J7: 7.31 | K7: 12.26 | L7: 27.63
A8: 2021-11-07 | B8: 1.47 | C8: 83.85 | D8: 04:00 | E8: 17:00 | F8: 21.3 | G8: 2021-11 | H8: 2021 | I8: 3.43 | J8: 11.71 | K8: 16.33 | L8: 50.99
A9: 2021-11-08 | B9: 15.22 | C9: 283.39 | D9: 01:00 | E9: 17:00 | F9: 107.68 | G9: 2021-11 | H9: 2021 | I9: 29.77 | J9: 125.1 | K9: 117.26 | L9: 176.68
A10: 2021-11-09 | B10: 6.48 | C10: 97.03 | D10: 23:00 | E10: 08:00 | F10: 51.83 | G10: 2021-11 | H10: 2021 | I10: 39.74 | J10: 92.38 | K10: 62.17 | L10: 37.05
A11: 2021-11-10 | B11: 3.55 | C11: 97.82 | D11: 23:00 | E11: 17:00 | F11: 29.89 | G11: 2021-11 | H11: 2021 | I11: 6.04 | J11: 37.76 | K11: 39.18 | L11: 44.96
A12: 2021-11-11 | B12: 2.93 | C12: 94.52 | D12: 00:00 | E12: 17:00 | F12: 24.34 | G12: 2021-11 | H12: 2021 | I12: 5.35 | J12: 26.9 | K12: 19.54 | L12: 49.67
A13: 2021-11-12 | B13: 11.01 | C13: 100.01 | D13: 00:00 | E13: 17:00 | F13: 69.17 | G13: 2021-11 | H13: 2021 | I13: 19.27 | J13: 97.77 | K13: 93.68 | L13: 92.84
... A1528: 2026-01-05 | B1528: 81.18 | C1528: 250.58 | D1528: 00:00 | E1528: 17:00 | F1528: 139.75 | G1528: 2026-01 | H1528: 2026 | I1528: 90.15 | J1528: 144.65 | K1528: 156.02 | L1528: 181.23

Sheet Priser SE4
A1: Datum | B1: Min EUR/MWh | C1: Max EUR/MWh | D1: Min timme | E1: Max timme | F1: Avg EUR/MWh | G1: Period | H1: År | I1: Natt avg | J1: Morgon avg | K1: Middag avg | L1: Kväll avg
A2: 2021-11-01 | B2: 13.13 | C2: 94.75 | D2: 01:00 | E2: 17:00 | F2: 60.64 | G2: 2021-11 | H2: 2021 | I2: 15.05 | J2: 81.21 | K2: 78.81 | L2: 85.56
A3: 2021-11-02 | B3: 3.43 | C3: 133.89 | D3: 03:00 | E3: 09:00 | F3: 86.84 | G3: 2021-11 | H3: 2021 | I3: 21.1 | J3: 131.65 | K3: 132.07 | L3: 117.46
A4: 2021-11-03 | B4: 14.96 | C4: 165.14 | D4: 02:00 | E4: 16:00 | F4: 103.13 | G4: 2021-11 | H4: 2021 | I4: 50.99 | J4: 138.38 | K4: 134.7 | L4: 127.17
A5: 2021-11-04 | B5: 18.82 | C5: 140.79 | D5: 23:00 | E5: 10:00 | F5: 96.84 | G5: 2021-11 | H5: 2021 | I5: 68.45 | J5: 135.4 | K5: 122.42 | L5: 103.36
A6: 2021-11-05 | B6: 7.33 | C6: 102.41 | D6: 23:00 | E6: 08:00 | F6: 58.51 | G6: 2021-11 | H6: 2021 | I6: 24.01 | J6: 100.1 | K6: 86.9 | L6: 58.78
A7: 2021-11-06 | B7: 1.82 | C7: 75.09 | D7: 02:00 | E7: 16:00 | F7: 14.32 | G7: 2021-11 | H7: 2021 | I7: 2.55 | J7: 7.31 | K7: 12.26 | L7: 27.63
A8: 2021-11-07 | B8: 1.47 | C8: 83.85 | D8: 04:00 | E8: 17:00 | F8: 26.81 | G8: 2021-11 | H8: 2021 | I8: 3.43 | J8: 11.71 | K8: 16.33 | L8: 76.17
A9: 2021-11-08 | B9: 15.22 | C9: 292.7 | D9: 01:00 | E9: 18:00 | F9: 142.35 | G9: 2021-11 | H9: 2021 | I9: 43.29 | J9: 125.32 | K9: 188.82 | L9: 240.74
A10: 2021-11-09 | B10: 6.48 | C10: 183.09 | D10: 23:00 | E10: 07:00 | F10: 80.9 | G10: 2021-11 | H10: 2021 | I10: 93.07 | J10: 142.96 | K10: 80.09 | L10: 43.58
A11: 2021-11-10 | B11: 3.81 | C11: 193.72 | D11: 02:00 | E11: 17:00 | F11: 106.41 | G11: 2021-11 | H11: 2021 | I11: 15.68 | J11: 128.73 | K11: 157.5 | L11: 156.38
A12: 2021-11-11 | B12: 55.02 | C12: 162.22 | D12: 22:00 | E12: 16:00 | F12: 121.67 | G12: 2021-11 | H12: 2021 | I12: 91.29 | J12: 141.28 | K12: 148.49 | L12: 140.23
A13: 2021-11-12 | B13: 79.53 | C13: 209.61 | D13: 23:00 | E13: 08:00 | F13: 138.35 | G13: 2021-11 | H13: 2021 | I13: 104.32 | J13: 200.51 | K13: 163.57 | L13: 124.86
... A1528: 2026-01-05 | B1528: 81.18 | C1528: 250.58 | D1528: 00:00 | E1528: 17:00 | F1528: 139.78 | G1528: 2026-01 | H1528: 2026 | I1528: 90.17 | J1528: 144.66 | K1528: 156.08 | L1528: 181.25

Sheet Beräkningar
A1: Datum | B1: Zon | C1: Min EUR | D1: Max EUR | E1: Spread | F1: Revenue 1C | G1: Profitable 1C | H1: Cycle1 Rev | I1: Cycle2 Rev | J1: Revenue 2C | K1: Profitable 2C | L1: År
A2: ='Priser SE1'!A2 | B2: SE1 | C2: ='Priser SE1'!B2 | D2: ='Priser SE1'!C2 | E2: =D2-C2 | F2: =IFERROR(MAX(0,D2*Efficiency-C2),0) | G2: =IF(F2>0,1,0) | H2: =IFERROR(MAX(0,'Priser SE1'!J2*Efficiency-'Priser SE1'!I2),0) | I2: =IFERROR(MAX(0,'Priser SE1'!L2*Efficiency-'Priser SE1'!K2),0) | J2: =IFERROR(H2+I2,0) | K2: =IF(J2>0,1,0) | L2: ='Priser SE1'!H2
A3: ='Priser SE1'!A3 | B3: SE1 | C3: ='Priser SE1'!B3 | D3: ='Priser SE1'!C3 | E3: =D3-C3 | F3: =IFERROR(MAX(0,D3*Efficiency-C3),0) | G3: =IF(F3>0,1,0) | H3: =IFERROR(MAX(0,'Priser SE1'!J3*Efficiency-'Priser SE1'!I3),0) | I3: =IFERROR(MAX(0,'Priser SE1'!L3*Efficiency-'Priser SE1'!K3),0) | J3: =IFERROR(H3+I3,0) | K3: =IF(J3>0,1,0) | L3: ='Priser SE1'!H3
A4: ='Priser SE1'!A4 | B4: SE1 | C4: ='Priser SE1'!B4 | D4: ='Priser SE1'!C4 | E4: =D4-C4 | F4: =IFERROR(MAX(0,D4*Efficiency-C4),0) | G4: =IF(F4>0,1,0) | H4: =IFERROR(MAX(0,'Priser SE1'!J4*Efficiency-'Priser SE1'!I4),0) | I4: =IFERROR(MAX(0,'Priser SE1'!L4*Efficiency-'Priser SE1'!K4),0) | J4: =IFERROR(H4+I4,0) | K4: =IF(J4>0,1,0) | L4: ='Priser SE1'!H4
A5: ='Priser SE1'!A5 | B5: SE1 | C5: ='Priser SE1'!B5 | D5: ='Priser SE1'!C5 | E5: =D5-C5 | F5: =IFERROR(MAX(0,D5*Efficiency-C5),0) | G5: =IF(F5>0,1,0) | H5: =IFERROR(MAX(0,'Priser SE1'!J5*Efficiency-'Priser SE1'!I5),0) | I5: =IFERROR(MAX(0,'Priser SE1'!L5*Efficiency-'Priser SE1'!K5),0) | J5: =IFERROR(H5+I5,0) | K5: =IF(J5>0,1,0) | L5: ='Priser SE1'!H5
A6: ='Priser SE1'!A6 | B6: SE1 | C6: ='Priser SE1'!B6 | D6: ='Priser SE1'!C6 | E6: =D6-C6 | F6: =IFERROR(MAX(0,D6*Efficiency-C6),0) | G6: =IF(F6>0,1,0) | H6: =IFERROR(MAX(0,'Priser SE1'!J6*Efficiency-'Priser SE1'!I6),0) | I6: =IFERROR(MAX(0,'Priser SE1'!L6*Efficiency-'Priser SE1'!K6),0) | J6: =IFERROR(H6+I6,0) | K6: =IF(J6>0,1,0) | L6: ='Priser SE1'!H6
A7: ='Priser SE1'!A7 | B7: SE1 | C7: ='Priser SE1'!B7 | D7: ='Priser SE1'!C7 | E7: =D7-C7 | F7: =IFERROR(MAX(0,D7*Efficiency-C7),0) | G7: =IF(F7>0,1,0) | H7: =IFERROR(MAX(0,'Priser SE1'!J7*Efficiency-'Priser SE1'!I7),0) | I7: =IFERROR(MAX(0,'Priser SE1'!L7*Efficiency-'Priser SE1'!K7),0) | J7: =IFERROR(H7+I7,0) | K7: =IF(J7>0,1,0) | L7: ='Priser SE1'!H7
A8: ='Priser SE1'!A8 | B8: SE1 | C8: ='Priser SE1'!B8 | D8: ='Priser SE1'!C8 | E8: =D8-C8 | F8: =IFERROR(MAX(0,D8*Efficiency-C8),0) | G8: =IF(F8>0,1,0) | H8: =IFERROR(MAX(0,'Priser SE1'!J8*Efficiency-'Priser SE1'!I8),0) | I8: =IFERROR(MAX(0,'Priser SE1'!L8*Efficiency-'Priser SE1'!K8),0) | J8: =IFERROR(H8+I8,0) | K8: =IF(J8>0,1,0) | L8: ='Priser SE1'!H8
A9: ='Priser SE1'!A9 | B9: SE1 | C9: ='Priser SE1'!B9 | D9: ='Priser SE1'!C9 | E9: =D9-C9 | F9: =IFERROR(MAX(0,D9*Efficiency-C9),0) | G9: =IF(F9>0,1,0) | H9: =IFERROR(MAX(0,'Priser SE1'!J9*Efficiency-'Priser SE1'!I9),0) | I9: =IFERROR(MAX(0,'Priser SE1'!L9*Efficiency-'Priser SE1'!K9),0) | J9: =IFERROR(H9+I9,0) | K9: =IF(J9>0,1,0) | L9: ='Priser SE1'!H9
A10: ='Priser SE1'!A10 | B10: SE1 | C10: ='Priser SE1'!B10 | D10: ='Priser SE1'!C10 | E10: =D10-C10 | F10: =IFERROR(MAX(0,D10*Efficiency-C10),0) | G10: =IF(F10>0,1,0) | H10: =IFERROR(MAX(0,'Priser SE1'!J10*Efficiency-'Priser SE1'!I10),0) | I10: =IFERROR(MAX(0,'Priser SE1'!L10*Efficiency-'Priser SE1'!K10),0) | J10: =IFERROR(H10+I10,0) | K10: =IF(J10>0,1,0) | L10: ='Priser SE1'!H10
A11: ='Priser SE1'!A11 | B11: SE1 | C11: ='Priser SE1'!B11 | D11: ='Priser SE1'!C11 | E11: =D11-C11 | F11: =IFERROR(MAX(0,D11*Efficiency-C11),0) | G11: =IF(F11>0,1,0) | H11: =IFERROR(MAX(0,'Priser SE1'!J11*Efficiency-'Priser SE1'!I11),0) | I11: =IFERROR(MAX(0,'Priser SE1'!L11*Efficiency-'Priser SE1'!K11),0) | J11: =IFERROR(H11+I11,0) | K11: =IF(J11>0,1,0) | L11: ='Priser SE1'!H11
A12: ='Priser SE1'!A12 | B12: SE1 | C12: ='Priser SE1'!B12 | D12: ='Priser SE1'!C12 | E12: =D12-C12 | F12: =IFERROR(MAX(0,D12*Efficiency-C12),0) | G12: =IF(F12>0,1,0) | H12: =IFERROR(MAX(0,'Priser SE1'!J12*Efficiency-'Priser SE1'!I12),0) | I12: =IFERROR(MAX(0,'Priser SE1'!L12*Efficiency-'Priser SE1'!K12),0) | J12: =IFERROR(H12+I12,0) | K12: =IF(J12>0,1,0) | L12: ='Priser SE1'!H12
A13: ='Priser SE1'!A13 | B13: SE1 | C13: ='Priser SE1'!B13 | D13: ='Priser SE1'!C13 | E13: =D13-C13 | F13: =IFERROR(MAX(0,D13*Efficiency-C13),0) | G13: =IF(F13>0,1,0) | H13: =IFERROR(MAX(0,'Priser SE1'!J13*Efficiency-'Priser SE1'!I13),0) | I13: =IFERROR(MAX(0,'Priser SE1'!L13*Efficiency-'Priser SE1'!K13),0) | J13: =IFERROR(H13+I13,0) | K13: =IF(J13>0,1,0) | L13: ='Priser SE1'!H13
... A1528: ='Priser SE1'!A1528 | B1528: SE1 | C1528: ='Priser SE1'!B1528 | D1528: ='Priser SE1'!C1528 | E1528: =D1528-C1528 | F1528: =IFERROR(MAX(0,D1528*Efficiency-C1528),0) | G1528: =IF(F1528>0,1,0) | H1528: =IFERROR(MAX(0,'Priser SE1'!J1528*Efficiency-'Priser SE1'!I1528),0) | I1528: =IFERROR(MAX(0,'Priser SE1'!L1528*Efficiency-'Priser SE1'!K1528),0) | J1528: =IFERROR(H1528+I1528,0) | K1528: =IF(J1528>0,1,0) | L1528: ='Priser SE1'!H1528
A1529: ='Priser SE2'!A2 | B1529: SE2 | C1529: ='Priser SE2'!B2 | D1529: ='Priser SE2'!C2 | E1529: =D1529-C1529 | F1529: =IFERROR(MAX(0,D1529*Efficiency-C1529),0) | G1529: =IF(F1529>0,1,0) | H1529: =IFERROR(MAX(0,'Priser SE2'!J2*Efficiency-'Priser SE2'!I2),0) | I1529: =IFERROR(MAX(0,'Priser SE2'!L2*Efficiency-'Priser SE2'!K2),0) | J1529: =IFERROR(H1529+I1529,0) | K1529: =IF(J1529>0,1,0) | L1529: ='Priser SE2'!H2
A1530: ='Priser SE2'!A3 | B1530: SE2 | C1530: ='Priser SE2'!B3 | D1530: ='Priser SE2'!C3 | E1530: =D1530-C1530 | F1530: =IFERROR(MAX(0,D1530*Efficiency-C1530),0) | G1530: =IF(F1530>0,1,0) | H1530: =IFERROR(MAX(0,'Priser SE2'!J3*Efficiency-'Priser SE2'!I3),0) | I1530: =IFERROR(MAX(0,'Priser SE2'!L3*Efficiency-'Priser SE2'!K3),0) | J1530: =IFERROR(H1530+I1530,0) | K1530: =IF(J1530>0,1,0) | L1530: ='Priser SE2'!H3
A1531: ='Priser SE2'!A4 | B1531: SE2 | C1531: ='Priser SE2'!B4 | D1531: ='Priser SE2'!C4 | E1531: =D1531-C1531 | F1531: =IFERROR(MAX(0,D1531*Efficiency-C1531),0) | G1531: =IF(F1531>0,1,0) | H1531: =IFERROR(MAX(0,'Priser SE2'!J4*Efficiency-'Priser SE2'!I4),0) | I1531: =IFERROR(MAX(0,'Priser SE2'!L4*Efficiency-'Priser SE2'!K4),0) | J1531: =IFERROR(H1531+I1531,0) | K1531: =IF(J1531>0,1,0) | L1531: ='Priser SE2'!H4
A1532: ='Priser SE2'!A5 | B1532: SE2 | C1532: ='Priser SE2'!B5 | D1532: ='Priser SE2'!C5 | E1532: =D1532-C1532 | F1532: =IFERROR(MAX(0,D1532*Efficiency-C1532),0) | G1532: =IF(F1532>0,1,0) | H1532: =IFERROR(MAX(0,'Priser SE2'!J5*Efficiency-'Priser SE2'!I5),0) | I1532: =IFERROR(MAX(0,'Priser SE2'!L5*Efficiency-'Priser SE2'!K5),0) | J1532: =IFERROR(H1532+I1532,0) | K1532: =IF(J1532>0,1,0) | L1532: ='Priser SE2'!H5
A1533: ='Priser SE2'!A6 | B1533: SE2 | C1533: ='Priser SE2'!B6 | D1533: ='Priser SE2'!C6 | E1533: =D1533-C1533 | F1533: =IFERROR(MAX(0,D1533*Efficiency-C1533),0) | G1533: =IF(F1533>0,1,0) | H1533: =IFERROR(MAX(0,'Priser SE2'!J6*Efficiency-'Priser SE2'!I6),0) | I1533: =IFERROR(MAX(0,'Priser SE2'!L6*Efficiency-'Priser SE2'!K6),0) | J1533: =IFERROR(H1533+I1533,0) | K1533: =IF(J1533>0,1,0) | L1533: ='Priser SE2'!H6
A1534: ='Priser SE2'!A7 | B1534: SE2 | C1534: ='Priser SE2'!B7 | D1534: ='Priser SE2'!C7 | E1534: =D1534-C1534 | F1534: =IFERROR(MAX(0,D1534*Efficiency-C1534),0) | G1534: =IF(F1534>0,1,0) | H1534: =IFERROR(MAX(0,'Priser SE2'!J7*Efficiency-'Priser SE2'!I7),0) | I1534: =IFERROR(MAX(0,'Priser SE2'!L7*Efficiency-'Priser SE2'!K7),0) | J1534: =IFERROR(H1534+I1534,0) | K1534: =IF(J1534>0,1,0) | L1534: ='Priser SE2'!H7
A1535: ='Priser SE2'!A8 | B1535: SE2 | C1535: ='Priser SE2'!B8 | D1535: ='Priser SE2'!C8 | E1535: =D1535-C1535 | F1535: =IFERROR(MAX(0,D1535*Efficiency-C1535),0) | G1535: =IF(F1535>0,1,0) | H1535: =IFERROR(MAX(0,'Priser SE2'!J8*Efficiency-'Priser SE2'!I8),0) | I1535: =IFERROR(MAX(0,'Priser SE2'!L8*Efficiency-'Priser SE2'!K8),0) | J1535: =IFERROR(H1535+I1535,0) | K1535: =IF(J1535>0,1,0) | L1535: ='Priser SE2'!H8
A1536: ='Priser SE2'!A9 | B1536: SE2 | C1536: ='Priser SE2'!B9 | D1536: ='Priser SE2'!C9 | E1536: =D1536-C1536 | F1536: =IFERROR(MAX(0,D1536*Efficiency-C1536),0) | G1536: =IF(F1536>0,1,0) | H1536: =IFERROR(MAX(0,'Priser SE2'!J9*Efficiency-'Priser SE2'!I9),0) | I1536: =IFERROR(MAX(0,'Priser SE2'!L9*Efficiency-'Priser SE2'!K9),0) | J1536: =IFERROR(H1536+I1536,0) | K1536: =IF(J1536>0,1,0) | L1536: ='Priser SE2'!H9
A1537: ='Priser SE2'!A10 | B1537: SE2 | C1537: ='Priser SE2'!B10 | D1537: ='Priser SE2'!C10 | E1537: =D1537-C1537 | F1537: =IFERROR(MAX(0,D1537*Efficiency-C1537),0) | G1537: =IF(F1537>0,1,0) | H1537: =IFERROR(MAX(0,'Priser SE2'!J10*Efficiency-'Priser SE2'!I10),0) | I1537: =IFERROR(MAX(0,'Priser SE2'!L10*Efficiency-'Priser SE2'!K10),0) | J1537: =IFERROR(H1537+I1537,0) | K1537: =IF(J1537>0,1,0) | L1537: ='Priser SE2'!H10
A1538: ='Priser SE2'!A11 | B1538: SE2 | C1538: ='Priser SE2'!B11 | D1538: ='Priser SE2'!C11 | E1538: =D1538-C1538 | F1538: =IFERROR(MAX(0,D1538*Efficiency-C1538),0) | G1538: =IF(F1538>0,1,0) | H1538: =IFERROR(MAX(0,'Priser SE2'!J11*Efficiency-'Priser SE2'!I11),0) | I1538: =IFERROR(MAX(0,'Priser SE2'!L11*Efficiency-'Priser SE2'!K11),0) | J1538: =IFERROR(H1538+I1538,0) | K1538: =IF(J1538>0,1,0) | L1538: ='Priser SE2'!H11
A1539: ='Priser SE2'!A12 | B1539: SE2 | C1539: ='Priser SE2'!B12 | D1539: ='Priser SE2'!C12 | E1539: =D1539-C1539 | F1539: =IFERROR(MAX(0,D1539*Efficiency-C1539),0) | G1539: =IF(F1539>0,1,0) | H1539: =IFERROR(MAX(0,'Priser SE2'!J12*Efficiency-'Priser SE2'!I12),0) | I1539: =IFERROR(MAX(0,'Priser SE2'!L12*Efficiency-'Priser SE2'!K12),0) | J1539: =IFERROR(H1539+I1539,0) | K1539: =IF(J1539>0,1,0) | L1539: ='Priser SE2'!H12
A1540: ='Priser SE2'!A13 | B1540: SE2 | C1540: ='Priser SE2'!B13 | D1540: ='Priser SE2'!C13 | E1540: =D1540-C1540 | F1540: =IFERROR(MAX(0,D1540*Efficiency-C1540),0) | G1540: =IF(F1540>0,1,0) | H1540: =IFERROR(MAX(0,'Priser SE2'!J13*Efficiency-'Priser SE2'!I13),0) | I1540: =IFERROR(MAX(0,'Priser SE2'!L13*Efficiency-'Priser SE2'!K13),0) | J1540: =IFERROR(H1540+I1540,0) | K1540: =IF(J1540>0,1,0) | L1540: ='Priser SE2'!H13
... A3055: ='Priser SE2'!A1528 | B3055: SE2 | C3055: ='Priser SE2'!B1528 | D3055: ='Priser SE2'!C1528 | E3055: =D3055-C3055 | F3055: =IFERROR(MAX(0,D3055*Efficiency-C3055),0) | G3055: =IF(F3055>0,1,0) | H3055: =IFERROR(MAX(0,'Priser SE2'!J1528*Efficiency-'Priser SE2'!I1528),0) | I3055: =IFERROR(MAX(0,'Priser SE2'!L1528*Efficiency-'Priser SE2'!K1528),0) | J3055: =IFERROR(H3055+I3055,0) | K3055: =IF(J3055>0,1,0) | L3055: ='Priser SE2'!H1528
A3056: ='Priser SE3'!A2 | B3056: SE3 | C3056: ='Priser SE3'!B2 | D3056: ='Priser SE3'!C2 | E3056: =D3056-C3056 | F3056: =IFERROR(MAX(0,D3056*Efficiency-C3056),0) | G3056: =IF(F3056>0,1,0) | H3056: =IFERROR(MAX(0,'Priser SE3'!J2*Efficiency-'Priser SE3'!I2),0) | I3056: =IFERROR(MAX(0,'Priser SE3'!L2*Efficiency-'Priser SE3'!K2),0) | J3056: =IFERROR(H3056+I3056,0) | K3056: =IF(J3056>0,1,0) | L3056: ='Priser SE3'!H2
A3057: ='Priser SE3'!A3 | B3057: SE3 | C3057: ='Priser SE3'!B3 | D3057: ='Priser SE3'!C3 | E3057: =D3057-C3057 | F3057: =IFERROR(MAX(0,D3057*Efficiency-C3057),0) | G3057: =IF(F3057>0,1,0) | H3057: =IFERROR(MAX(0,'Priser SE3'!J3*Efficiency-'Priser SE3'!I3),0) | I3057: =IFERROR(MAX(0,'Priser SE3'!L3*Efficiency-'Priser SE3'!K3),0) | J3057: =IFERROR(H3057+I3057,0) | K3057: =IF(J3057>0,1,0) | L3057: ='Priser SE3'!H3
A3058: ='Priser SE3'!A4 | B3058: SE3 | C3058: ='Priser SE3'!B4 | D3058: ='Priser SE3'!C4 | E3058: =D3058-C3058 | F3058: =IFERROR(MAX(0,D3058*Efficiency-C3058),0) | G3058: =IF(F3058>0,1,0) | H3058: =IFERROR(MAX(0,'Priser SE3'!J4*Efficiency-'Priser SE3'!I4),0) | I3058: =IFERROR(MAX(0,'Priser SE3'!L4*Efficiency-'Priser SE3'!K4),0) | J3058: =IFERROR(H3058+I3058,0) | K3058: =IF(J3058>0,1,0) | L3058: ='Priser SE3'!H4
A3059: ='Priser SE3'!A5 | B3059: SE3 | C3059: ='Priser SE3'!B5 | D3059: ='Priser SE3'!C5 | E3059: =D3059-C3059 | F3059: =IFERROR(MAX(0,D3059*Efficiency-C3059),0) | G3059: =IF(F3059>0,1,0) | H3059: =IFERROR(MAX(0,'Priser SE3'!J5*Efficiency-'Priser SE3'!I5),0) | I3059: =IFERROR(MAX(0,'Priser SE3'!L5*Efficiency-'Priser SE3'!K5),0) | J3059: =IFERROR(H3059+I3059,0) | K3059: =IF(J3059>0,1,0) | L3059: ='Priser SE3'!H5
A3060: ='Priser SE3'!A6 | B3060: SE3 | C3060: ='Priser SE3'!B6 | D3060: ='Priser SE3'!C6 | E3060: =D3060-C3060 | F3060: =IFERROR(MAX(0,D3060*Efficiency-C3060),0) | G3060: =IF(F3060>0,1,0) | H3060: =IFERROR(MAX(0,'Priser SE3'!J6*Efficiency-'Priser SE3'!I6),0) | I3060: =IFERROR(MAX(0,'Priser SE3'!L6*Efficiency-'Priser SE3'!K6),0) | J3060: =IFERROR(H3060+I3060,0) | K3060: =IF(J3060>0,1,0) | L3060: ='Priser SE3'!H6
A3061: ='Priser SE3'!A7 | B3061: SE3 | C3061: ='Priser SE3'!B7 | D3061: ='Priser SE3'!C7 | E3061: =D3061-C3061 | F3061: =IFERROR(MAX(0,D3061*Efficiency-C3061),0) | G3061: =IF(F3061>0,1,0) | H3061: =IFERROR(MAX(0,'Priser SE3'!J7*Efficiency-'Priser SE3'!I7),0) | I3061: =IFERROR(MAX(0,'Priser SE3'!L7*Efficiency-'Priser SE3'!K7),0) | J3061: =IFERROR(H3061+I3061,0) | K3061: =IF(J3061>0,1,0) | L3061: ='Priser SE3'!H7
A3062: ='Priser SE3'!A8 | B3062: SE3 | C3062: ='Priser SE3'!B8 | D3062: ='Priser SE3'!C8 | E3062: =D3062-C3062 | F3062: =IFERROR(MAX(0,D3062*Efficiency-C3062),0) | G3062: =IF(F3062>0,1,0) | H3062: =IFERROR(MAX(0,'Priser SE3'!J8*Efficiency-'Priser SE3'!I8),0) | I3062: =IFERROR(MAX(0,'Priser SE3'!L8*Efficiency-'Priser SE3'!K8),0) | J3062: =IFERROR(H3062+I3062,0) | K3062: =IF(J3062>0,1,0) | L3062: ='Priser SE3'!H8
A3063: ='Priser SE3'!A9 | B3063: SE3 | C3063: ='Priser SE3'!B9 | D3063: ='Priser SE3'!C9 | E3063: =D3063-C3063 | F3063: =IFERROR(MAX(0,D3063*Efficiency-C3063),0) | G3063: =IF(F3063>0,1,0) | H3063: =IFERROR(MAX(0,'Priser SE3'!J9*Efficiency-'Priser SE3'!I9),0) | I3063: =IFERROR(MAX(0,'Priser SE3'!L9*Efficiency-'Priser SE3'!K9),0) | J3063: =IFERROR(H3063+I3063,0) | K3063: =IF(J3063>0,1,0) | L3063: ='Priser SE3'!H9
A3064: ='Priser SE3'!A10 | B3064: SE3 | C3064: ='Priser SE3'!B10 | D3064: ='Priser SE3'!C10 | E3064: =D3064-C3064 | F3064: =IFERROR(MAX(0,D3064*Efficiency-C3064),0) | G3064: =IF(F3064>0,1,0) | H3064: =IFERROR(MAX(0,'Priser SE3'!J10*Efficiency-'Priser SE3'!I10),0) | I3064: =IFERROR(MAX(0,'Priser SE3'!L10*Efficiency-'Priser SE3'!K10),0) | J3064: =IFERROR(H3064+I3064,0) | K3064: =IF(J3064>0,1,0) | L3064: ='Priser SE3'!H10
A3065: ='Priser SE3'!A11 | B3065: SE3 | C3065: ='Priser SE3'!B11 | D3065: ='Priser SE3'!C11 | E3065: =D3065-C3065 | F3065: =IFERROR(MAX(0,D3065*Efficiency-C3065),0) | G3065: =IF(F3065>0,1,0) | H3065: =IFERROR(MAX(0,'Priser SE3'!J11*Efficiency-'Priser SE3'!I11),0) | I3065: =IFERROR(MAX(0,'Priser SE3'!L11*Efficiency-'Priser SE3'!K11),0) | J3065: =IFERROR(H3065+I3065,0) | K3065: =IF(J3065>0,1,0) | L3065: ='Priser SE3'!H11
A3066: ='Priser SE3'!A12 | B3066: SE3 | C3066: ='Priser SE3'!B12 | D3066: ='Priser SE3'!C12 | E3066: =D3066-C3066 | F3066: =IFERROR(MAX(0,D3066*Efficiency-C3066),0) | G3066: =IF(F3066>0,1,0) | H3066: =IFERROR(MAX(0,'Priser SE3'!J12*Efficiency-'Priser SE3'!I12),0) | I3066: =IFERROR(MAX(0,'Priser SE3'!L12*Efficiency-'Priser SE3'!K12),0) | J3066: =IFERROR(H3066+I3066,0) | K3066: =IF(J3066>0,1,0) | L3066: ='Priser SE3'!H12
A3067: ='Priser SE3'!A13 | B3067: SE3 | C3067: ='Priser SE3'!B13 | D3067: ='Priser SE3'!C13 | E3067: =D3067-C3067 | F3067: =IFERROR(MAX(0,D3067*Efficiency-C3067),0) | G3067: =IF(F3067>0,1,0) | H3067: =IFERROR(MAX(0,'Priser SE3'!J13*Efficiency-'Priser SE3'!I13),0) | I3067: =IFERROR(MAX(0,'Priser SE3'!L13*Efficiency-'Priser SE3'!K13),0) | J3067: =IFERROR(H3067+I3067,0) | K3067: =IF(J3067>0,1,0) | L3067: ='Priser SE3'!H13
... A4582: ='Priser SE3'!A1528 | B4582: SE3 | C4582: ='Priser SE3'!B1528 | D4582: ='Priser SE3'!C1528 | E4582: =D4582-C4582 | F4582: =IFERROR(MAX(0,D4582*Efficiency-C4582),0) | G4582: =IF(F4582>0,1,0) | H4582: =IFERROR(MAX(0,'Priser SE3'!J1528*Efficiency-'Priser SE3'!I1528),0) | I4582: =IFERROR(MAX(0,'Priser SE3'!L1528*Efficiency-'Priser SE3'!K1528),0) | J4582: =IFERROR(H4582+I4582,0) | K4582: =IF(J4582>0,1,0) | L4582: ='Priser SE3'!H1528
...

Sheet Månadssammanfattning
A1: Period | B1: Zon | C1: Antal dagar | D1: Avg Spread | E1: Median Spread | F1: Max Spread | G1: Revenue 1C | H1: Profitable 1C % | I1: Revenue 2C | J1: Profitable 2C %
A2: 2021-11 | B2: SE1 | C2: =IFERROR(SUMPRODUCT((Beräkningar!B:B=B2)*('Priser SE1'!G:G=A2)*1),0) | D2: =IFERROR(AVERAGEIFS(Beräkningar!E:E,Beräkningar!B:B,B2,'Priser SE1'!G:G,A2),0) | E2: 11.02 | F2: =IFERROR(MAXIFS(Beräkningar!E:E,Beräkningar!B:B,B2,'Priser SE1'!G:G,A2),0) | G2: =IFERROR(SUMIFS(Beräkningar!F:F,Beräkningar!B:B,B2,'Priser SE1'!G:G,A2),0) | H2: =IFERROR(IF(C2>0,SUMIFS(Beräkningar!G:G,Beräkningar!B:B,B2,'Priser SE1'!G:G,A2)/C2,0),0) | I2: =IFERROR(SUMIFS(Beräkningar!J:J,Beräkningar!B:B,B2,'Priser SE1'!G:G,A2),0) | J2: =IFERROR(IF(C2>0,SUMIFS(Beräkningar!K:K,Beräkningar!B:B,B2,'Priser SE1'!G:G,A2)/C2,0),0)
A3: 2021-11 | B3: SE2 | C3: =IFERROR(SUMPRODUCT((Beräkningar!B:B=B3)*('Priser SE2'!G:G=A3)*1),0) | D3: =IFERROR(AVERAGEIFS(Beräkningar!E:E,Beräkningar!B:B,B3,'Priser SE2'!G:G,A3),0) | E3: 11.02 | F3: =IFERROR(MAXIFS(Beräkningar!E:E,Beräkningar!B:B,B3,'Priser SE2'!G:G,A3),0) | G3: =IFERROR(SUMIFS(Beräkningar!F:F,Beräkningar!B:B,B3,'Priser SE2'!G:G,A3),0) | H3: =IFERROR(IF(C3>0,SUMIFS(Beräkningar!G:G,Beräkningar!B:B,B3,'Priser SE2'!G:G,A3)/C3,0),0) | I3: =IFERROR(SUMIFS(Beräkningar!J:J,Beräkningar!B:B,B3,'Priser SE2'!G:G,A3),0) | J3: =IFERROR(IF(C3>0,SUMIFS(Beräkningar!K:K,Beräkningar!B:B,B3,'Priser SE2'!G:G,A3)/C3,0),0)
A4: 2021-11 | B4: SE3 | C4: =IFERROR(SUMPRODUCT((Beräkningar!B:B=B4)*('Priser SE3'!G:G=A4)*1),0) | D4: =IFERROR(AVERAGEIFS(Beräkningar!E:E,Beräkningar!B:B,B4,'Priser SE3'!G:G,A4),0) | E4: 93.85 | F4: =IFERROR(MAXIFS(Beräkningar!E:E,Beräkningar!B:B,B4,'Priser SE3'!G:G,A4),0) | G4: =IFERROR(SUMIFS(Beräkningar!F:F,Beräkningar!B:B,B4,'Priser SE3'!G:G,A4),0) | H4: =IFERROR(IF(C4>0,SUMIFS(Beräkningar!G:G,Beräkningar!B:B,B4,'Priser SE3'!G:G,A4)/C4,0),0) | I4: =IFERROR(SUMIFS(Beräkningar!J:J,Beräkningar!B:B,B4,'Priser SE3'!G:G,A4),0) | J4: =IFERROR(IF(C4>0,SUMIFS(Beräkningar!K:K,Beräkningar!B:B,B4,'Priser SE3'!G:G,A4)/C4,0),0)
A5: 2021-11 | B5: SE4 | C5: =IFERROR(SUMPRODUCT((Beräkningar!B:B=B5)*('Priser SE4'!G:G=A5)*1),0) | D5: =IFERROR(AVERAGEIFS(Beräkningar!E:E,Beräkningar!B:B,B5,'Priser SE4'!G:G,A5),0) | E5: 139.63 | F5: =IFERROR(MAXIFS(Beräkningar!E:E,Beräkningar!B:B,B5,'Priser SE4'!G:G,A5),0) | G5: =IFERROR(SUMIFS(Beräkningar!F:F,Beräkningar!B:B,B5,'Priser SE4'!G:G,A5),0) | H5: =IFERROR(IF(C5>0,SUMIFS(Beräkningar!G:G,Beräkningar!B:B,B5,'Priser SE4'!G:G,A5)/C5,0),0) | I5: =IFERROR(SUMIFS(Beräkningar!J:J,Beräkningar!B:B,B5,'Priser SE4'!G:G,A5),0) | J5: =IFERROR(IF(C5>0,SUMIFS(Beräkningar!K:K,Beräkningar!B:B,B5,'Priser SE4'!G:G,A5)/C5,0),0)
A6: 2021-12 | B6: SE1 | C6: =IFERROR(SUMPRODUCT((Beräkningar!B:B=B6)*('Priser SE1'!G:G=A6)*1),0) | D6: =IFERROR(AVERAGEIFS(Beräkningar!E:E,Beräkningar!B:B,B6,'Priser SE1'!G:G,A6),0) | E6: 18.18 | F6: =IFERROR(MAXIFS(Beräkningar!E:E,Beräkningar!B:B,B6,'Priser SE1'!G:G,A6),0) | G6: =IFERROR(SUMIFS(Beräkningar!F:F,Beräkningar!B:B,B6,'Priser SE1'!G:G,A6),0) | H6: =IFERROR(IF(C6>0,SUMIFS(Beräkningar!G:G,Beräkningar!B:B,B6,'Priser SE1'!G:G,A6)/C6,0),0) | I6: =IFERROR(SUMIFS(Beräkningar!J:J,Beräkningar!B:B,B6,'Priser SE1'!G:G,A6),0) | J6: =IFERROR(IF(C6>0,SUMIFS(Beräkningar!K:K,Beräkningar!B:B,B6,'Priser SE1'!G:G,A6)/C6,0),0)
A7: 2021-12 | B7: SE2 | C7: =IFERROR(SUMPRODUCT((Beräkningar!B:B=B7)*('Priser SE2'!G:G=A7)*1),0) | D7: =IFERROR(AVERAGEIFS(Beräkningar!E:E,Beräkningar!B:B,B7,'Priser SE2'!G:G,A7),0) | E7: 18.18 | F7: =IFERROR(MAXIFS(Beräkningar!E:E,Beräkningar!B:B,B7,'Priser SE2'!G:G,A7),0) | G7: =IFERROR(SUMIFS(Beräkningar!F:F,Beräkningar!B:B,B7,'Priser SE2'!G:G,A7),0) | H7: =IFERROR(IF(C7>0,SUMIFS(Beräkningar!G:G,Beräkningar!B:B,B7,'Priser SE2'!G:G,A7)/C7,0),0) | I7: =IFERROR(SUMIFS(Beräkningar!J:J,Beräkningar!B:B,B7,'Priser SE2'!G:G,A7),0) | J7: =IFERROR(IF(C7>0,SUMIFS(Beräkningar!K:K,Beräkningar!B:B,B7,'Priser SE2'!G:G,A7)/C7,0),0)
A8: 2021-12 | B8: SE3 | C8: =IFERROR(SUMPRODUCT((Beräkningar!B:B=B8)*('Priser SE3'!G:G=A8)*1),0) | D8: =IFERROR(AVERAGEIFS(Beräkningar!E:E,Beräkningar!B:B,B8,'Priser SE3'!G:G,A8),0) | E8: 161.94 | F8: =IFERROR(MAXIFS(Beräkningar!E:E,Beräkningar!B:B,B8,'Priser SE3'!G:G,A8),0) | G8: =IFERROR(SUMIFS(Beräkningar!F:F,Beräkningar!B:B,B8,'Priser SE3'!G:G,A8),0) | H8: =IFERROR(IF(C8>0,SUMIFS(Beräkningar!G:G,Beräkningar!B:B,B8,'Priser SE3'!G:G,A8)/C8,0),0) | I8: =IFERROR(SUMIFS(Beräkningar!J:J,Beräkningar!B:B,B8,'Priser SE3'!G:G,A8),0) | J8: =IFERROR(IF(C8>0,SUMIFS(Beräkningar!K:K,Beräkningar!B:B,B8,'Priser SE3'!G:G,A8)/C8,0),0)
A9: 2021-12 | B9: SE4 | C9: =IFERROR(SUMPRODUCT((Beräkningar!B:B=B9)*('Priser SE4'!G:G=A9)*1),0) | D9: =IFERROR(AVERAGEIFS(Beräkningar!E:E,Beräkningar!B:B,B9,'Priser SE4'!G:G,A9),0) | E9: 160.89 | F9: =IFERROR(MAXIFS(Beräkningar!E:E,Beräkningar!B:B,B9,'Priser SE4'!G:G,A9),0) | G9: =IFERROR(SUMIFS(Beräkningar!F:F,Beräkningar!B:B,B9,'Priser SE4'!G:G,A9),0) | H9: =IFERROR(IF(C9>0,SUMIFS(Beräkningar!G:G,Beräkningar!B:B,B9,'Priser SE4'!G:G,A9)/C9,0),0) | I9: =IFERROR(SUMIFS(Beräkningar!J:J,Beräkningar!B:B,B9,'Priser SE4'!G:G,A9),0) | J9: =IFERROR(IF(C9>0,SUMIFS(Beräkningar!K:K,Beräkningar!B:B,B9,'Priser SE4'!G:G,A9)/C9,0),0)
A10: 2021 | B10: TOTALT | C10: =SUM(C2:C9) | D10: =IFERROR(SUMPRODUCT(D2:D9,C2:C9)/SUM(C2:C9),0) | E10: =IFERROR(SUMPRODUCT(E2:E9,C2:C9)/SUM(C2:C9),0) | F10: =MAX(F2:F9) | G10: =SUM(G2:G9) | H10: =IFERROR(SUMPRODUCT(H2:H9,C2:C9)/SUM(C2:C9),0) | I10: =SUM(I2:I9) | J10: =IFERROR(SUMPRODUCT(J2:J9,C2:C9)/SUM(C2:C9),0)
A11: 2022-01 | B11: SE1 | C11: =IFERROR(SUMPRODUCT((Beräkningar!B:B=B11)*('Priser SE1'!G:G=A11)*1),0) | D11: =IFERROR(AVERAGEIFS(Beräkningar!E:E,Beräkningar!B:B,B11,'Priser SE1'!G:G,A11),0) | E11: 7.61 | F11: =IFERROR(MAXIFS(Beräkningar!E:E,Beräkningar!B:B,B11,'Priser SE1'!G:G,A11),0) | G11: =IFERROR(SUMIFS(Beräkningar!F:F,Beräkningar!B:B,B11,'Priser SE1'!G:G,A11),0) | H11: =IFERROR(IF(C11>0,SUMIFS(Beräkningar!G:G,Beräkningar!B:B,B11,'Priser SE1'!G:G,A11)/C11,0),0) | I11: =IFERROR(SUMIFS(Beräkningar!J:J,Beräkningar!B:B,B11,'Priser SE1'!G:G,A11),0) | J11: =IFERROR(IF(C11>0,SUMIFS(Beräkningar!K:K,Beräkningar!B:B,B11,'Priser SE1'!G:G,A11)/C11,0),0)
A12: 2022-01 | B12: SE2 | C12: =IFERROR(SUMPRODUCT((Beräkningar!B:B=B12)*('Priser SE2'!G:G=A12)*1),0) | D12: =IFERROR(AVERAGEIFS(Beräkningar!E:E,Beräkningar!B:B,B12,'Priser SE2'!G:G,A12),0) | E12: 7.61 | F12: =IFERROR(MAXIFS(Beräkningar!E:E,Beräkningar!B:B,B12,'Priser SE2'!G:G,A12),0) | G12: =IFERROR(SUMIFS(Beräkningar!F:F,Beräkningar!B:B,B12,'Priser SE2'!G:G,A12),0) | H12: =IFERROR(IF(C12>0,SUMIFS(Beräkningar!G:G,Beräkningar!B:B,B12,'Priser SE2'!G:G,A12)/C12,0),0) | I12: =IFERROR(SUMIFS(Beräkningar!J:J,Beräkningar!B:B,B12,'Priser SE2'!G:G,A12),0) | J12: =IFERROR(IF(C12>0,SUMIFS(Beräkningar!K:K,Beräkningar!B:B,B12,'Priser SE2'!G:G,A12)/C12,0),0)
A13: 2022-01 | B13: SE3 | C13: =IFERROR(SUMPRODUCT((Beräkningar!B:B=B13)*('Priser SE3'!G:G=A13)*1),0) | D13: =IFERROR(AVERAGEIFS(Beräkningar!E:E,Beräkningar!B:B,B13,'Priser SE3'!G:G,A13),0) | E13: 126.36 | F13: =IFERROR(MAXIFS(Beräkningar!E:E,Beräkningar!B:B,B13,'Priser SE3'!G:G,A13),0) | G13: =IFERROR(SUMIFS(Beräkningar!F:F,Beräkningar!B:B,B13,'Priser SE3'!G:G,A13),0) | H13: =IFERROR(IF(C13>0,SUMIFS(Beräkningar!G:G,Beräkningar!B:B,B13,'Priser SE3'!G:G,A13)/C13,0),0) | I13: =IFERROR(SUMIFS(Beräkningar!J:J,Beräkningar!B:B,B13,'Priser SE3'!G:G,A13),0) | J13: =IFERROR(IF(C13>0,SUMIFS(Beräkningar!K:K,Beräkningar!B:B,B13,'Priser SE3'!G:G,A13)/C13,0),0)
A14: 2022-01 | B14: SE4 | C14: =IFERROR(SUMPRODUCT((Beräkningar!B:B=B14)*('Priser SE4'!G:G=A14)*1),0) | D14: =IFERROR(AVERAGEIFS(Beräkningar!E:E,Beräkningar!B:B,B14,'Priser SE4'!G:G,A14),0) | E14: 130.28 | F14: =IFERROR(MAXIFS(Beräkningar!E:E,Beräkningar!B:B,B14,'Priser SE4'!G:G,A14),0) | G14: =IFERROR(SUMIFS(Beräkningar!F:F,Beräkningar!B:B,B14,'Priser SE4'!G:G,A14),0) | H14: =IFERROR(IF(C14>0,SUMIFS(Beräkningar!G:G,Beräkningar!B:B,B14,'Priser SE4'!G:G,A14)/C14,0),0) | I14: =IFERROR(SUMIFS(Beräkningar!J:J,Beräkningar!B:B,B14,'Priser SE4'!G:G,A14),0) | J14: =IFERROR(IF(C14>0,SUMIFS(Beräkningar!K:K,Beräkningar!B:B,B14,'Priser SE4'!G:G,A14)/C14,0),0)
A15: 2022-02 | B15: SE1 | C15: =IFERROR(SUMPRODUCT((Beräkningar!B:B=B15)*('Priser SE1'!G:G=A15)*1),0) | D15: =IFERROR(AVERAGEIFS(Beräkningar!E:E,Beräkningar!B:B,B15,'Priser SE1'!G:G,A15),0) | E15: 4.66 | F15: =IFERROR(MAXIFS(Beräkningar!E:E,Beräkningar!B:B,B15,'Priser SE1'!G:G,A15),0) | G15: =IFERROR(SUMIFS(Beräkningar!F:F,Beräkningar!B:B,B15,'Priser SE1'!G:G,A15),0) | H15: =IFERROR(IF(C15>0,SUMIFS(Beräkningar!G:G,Beräkningar!B:B,B15,'Priser SE1'!G:G,A15)/C15,0),0) | I15: =IFERROR(SUMIFS(Beräkningar!J:J,Beräkningar!B:B,B15,'Priser SE1'!G:G,A15),0) | J15: =IFERROR(IF(C15>0,SUMIFS(Beräkningar!K:K,Beräkningar!B:B,B15,'Priser SE1'!G:G,A15)/C15,0),0)
A16: 2022-02 | B16: SE2 | C16: =IFERROR(SUMPRODUCT((Beräkningar!B:B=B16)*('Priser SE2'!G:G=A16)*1),0) | D16: =IFERROR(AVERAGEIFS(Beräkningar!E:E,Beräkningar!B:B,B16,'Priser SE2'!G:G,A16),0) | E16: 4.66 | F16: =IFERROR(MAXIFS(Beräkningar!E:E,Beräkningar!B:B,B16,'Priser SE2'!G:G,A16),0) | G16: =IFERROR(SUMIFS(Beräkningar!F:F,Beräkningar!B:B,B16,'Priser SE2'!G:G,A16),0) | H16: =IFERROR(IF(C16>0,SUMIFS(Beräkningar!G:G,Beräkningar!B:B,B16,'Priser SE2'!G:G,A16)/C16,0),0) | I16: =IFERROR(SUMIFS(Beräkningar!J:J,Beräkningar!B:B,B16,'Priser SE2'!G:G,A16),0) | J16: =IFERROR(IF(C16>0,SUMIFS(Beräkningar!K:K,Beräkningar!B:B,B16,'Priser SE2'!G:G,A16)/C16,0),0)
A17: 2022-02 | B17: SE3 | C17: =IFERROR(SUMPRODUCT((Beräkningar!B:B=B17)*('Priser SE3'!G:G=A17)*1),0) | D17: =IFERROR(AVERAGEIFS(Beräkningar!E:E,Beräkningar!B:B,B17,'Priser SE3'!G:G,A17),0) | E17: 115.39 | F17: =IFERROR(MAXIFS(Beräkningar!E:E,Beräkningar!B:B,B17,'Priser SE3'!G:G,A17),0) | G17: =IFERROR(SUMIFS(Beräkningar!F:F,Beräkningar!B:B,B17,'Priser SE3'!G:G,A17),0) | H17: =IFERROR(IF(C17>0,SUMIFS(Beräkningar!G:G,Beräkningar!B:B,B17,'Priser SE3'!G:G,A17)/C17,0),0) | I17: =IFERROR(SUMIFS(Beräkningar!J:J,Beräkningar!B:B,B17,'Priser SE3'!G:G,A17),0) | J17: =IFERROR(IF(C17>0,SUMIFS(Beräkningar!K:K,Beräkningar!B:B,B17,'Priser SE3'!G:G,A17)/C17,0),0)
A18: 2022-02 | B18: SE4 | C18: =IFERROR(SUMPRODUCT((Beräkningar!B:B=B18)*('Priser SE4'!G:G=A18)*1),0) | D18: =IFERROR(AVERAGEIFS(Beräkningar!E:E,Beräkningar!B:B,B18,'Priser SE4'!G:G,A18),0) | E18: 114.24 | F18: =IFERROR(MAXIFS(Beräkningar!E:E,Beräkningar!B:B,B18,'Priser SE4'!G:G,A18),0) | G18: =IFERROR(SUMIFS(Beräkningar!F:F,Beräkningar!B:B,B18,'Priser SE4'!G:G,A18),0) | H18: =IFERROR(IF(C18>0,SUMIFS(Beräkningar!G:G,Beräkningar!B:B,B18,'Priser SE4'!G:G,A18)/C18,0),0) | I18: =IFERROR(SUMIFS(Beräkningar!J:J,Beräkningar!B:B,B18,'Priser SE4'!G:G,A18),0) | J18: =IFERROR(IF(C18>0,SUMIFS(Beräkningar!K:K,Beräkningar!B:B,B18,'Priser SE4'!G:G,A18)/C18,0),0)
A19: 2022-03 | B19: SE1 | C19: =IFERROR(SUMPRODUCT((Beräkningar!B:B=B19)*('Priser SE1'!G:G=A19)*1),0) | D19: =IFERROR(AVERAGEIFS(Beräkningar!E:E,Beräkningar!B:B,B19,'Priser SE1'!G:G,A19),0) | E19: 10.1 | F19: =IFERROR(MAXIFS(Beräkningar!E:E,Beräkningar!B:B,B19,'Priser SE1'!G:G,A19),0) | G19: =IFERROR(SUMIFS(Beräkningar!F:F,Beräkningar!B:B,B19,'Priser SE1'!G:G,A19),0) | H19: =IFERROR(IF(C19>0,SUMIFS(Beräkningar!G:G,Beräkningar!B:B,B19,'Priser SE1'!G:G,A19)/C19,0),0) | I19: =IFERROR(SUMIFS(Beräkningar!J:J,Beräkningar!B:B,B19,'Priser SE1'!G:G,A19),0) | J19: =IFERROR(IF(C19>0,SUMIFS(Beräkningar!K:K,Beräkningar!B:B,B19,'Priser SE1'!G:G,A19)/C19,0),0)
A20: 2022-03 | B20: SE2 | C20: =IFERROR(SUMPRODUCT((Beräkningar!B:B=B20)*('Priser SE2'!G:G=A20)*1),0) | D20: =IFERROR(AVERAGEIFS(Beräkningar!E:E,Beräkningar!B:B,B20,'Priser SE2'!G:G,A20),0) | E20: 10.1 | F20: =IFERROR(MAXIFS(Beräkningar!E:E,Beräkningar!B:B,B20,'Priser SE2'!G:G,A20),0) | G20: =IFERROR(SUMIFS(Beräkningar!F:F,Beräkningar!B:B,B20,'Priser SE2'!G:G,A20),0) | H20: =IFERROR(IF(C20>0,SUMIFS(Beräkningar!G:G,Beräkningar!B:B,B20,'Priser SE2'!G:G,A20)/C20,0),0) | I20: =IFERROR(SUMIFS(Beräkningar!J:J,Beräkningar!B:B,B20,'Priser SE2'!G:G,A20),0) | J20: =IFERROR(IF(C20>0,SUMIFS(Beräkningar!K:K,Beräkningar!B:B,B20,'Priser SE2'!G:G,A20)/C20,0),0)
A21: 2022-03 | B21: SE3 | C21: =IFERROR(SUMPRODUCT((Beräkningar!B:B=B21)*('Priser SE3'!G:G=A21)*1),0) | D21: =IFERROR(AVERAGEIFS(Beräkningar!E:E,Beräkningar!B:B,B21,'Priser SE3'!G:G,A21),0) | E21: 180.79 | F21: =IFERROR(MAXIFS(Beräkningar!E:E,Beräkningar!B:B,B21,'Priser SE3'!G:G,A21),0) | G21: =IFERROR(SUMIFS(Beräkningar!F:F,Beräkningar!B:B,B21,'Priser SE3'!G:G,A21),0) | H21: =IFERROR(IF(C21>0,SUMIFS(Beräkningar!G:G,Beräkningar!B:B,B21,'Priser SE3'!G:G,A21)/C21,0),0) | I21: =IFERROR(SUMIFS(Beräkningar!J:J,Beräkningar!B:B,B21,'Priser SE3'!G:G,A21),0) | J21: =IFERROR(IF(C21>0,SUMIFS(Beräkningar!K:K,Beräkningar!B:B,B21,'Priser SE3'!G:G,A21)/C21,0),0)
A22: 2022-03 | B22: SE4 | C22: =IFERROR(SUMPRODUCT((Beräkningar!B:B=B22)*('Priser SE4'!G:G=A22)*1),0) | D22: =IFERROR(AVERAGEIFS(Beräkningar!E:E,Beräkningar!B:B,B22,'Priser SE4'!G:G,A22),0) | E22: 241.66 | F22: =IFERROR(MAXIFS(Beräkningar!E:E,Beräkningar!B:B,B22,'Priser SE4'!G:G,A22),0) | G22: =IFERROR(SUMIFS(Beräkningar!F:F,Beräkningar!B:B,B22,'Priser SE4'!G:G,A22),0) | H22: =IFERROR(IF(C22>0,SUMIFS(Beräkningar!G:G,Beräkningar!B:B,B22,'Priser SE4'!G:G,A22)/C22,0),0) | I22: =IFERROR(SUMIFS(Beräkningar!J:J,Beräkningar!B:B,B22,'Priser SE4'!G:G,A22),0) | J22: =IFERROR(IF(C22>0,SUMIFS(Beräkningar!K:K,Beräkningar!B:B,B22,'Priser SE4'!G:G,A22)/C22,0),0)
A23: 2022-04 | B23: SE1 | C23: =IFERROR(SUMPRODUCT((Beräkningar!B:B=B23)*('Priser SE1'!G:G=A23)*1),0) | D23: =IFERROR(AVERAGEIFS(Beräkningar!E:E,Beräkningar!B:B,B23,'Priser SE1'!G:G,A23),0) | E23: 42.5 | F23: =IFERROR(MAXIFS(Beräkningar!E:E,Beräkningar!B:B,B23,'Priser SE1'!G:G,A23),0) | G23: =IFERROR(SUMIFS(Beräkningar!F:F,Beräkningar!B:B,B23,'Priser SE1'!G:G,A23),0) | H23: =IFERROR(IF(C23>0,SUMIFS(Beräkningar!G:G,Beräkningar!B:B,B23,'Priser SE1'!G:G,A23)/C23,0),0) | I23: =IFERROR(SUMIFS(Beräkningar!J:J,Beräkningar!B:B,B23,'Priser SE1'!G:G,A23),0) | J23: =IFERROR(IF(C23>0,SUMIFS(Beräkningar!K:K,Beräkningar!B:B,B23,'Priser SE1'!G:G,A23)/C23,0),0)
A24: 2022-04 | B24: SE2 | C24: =IFERROR(SUMPRODUCT((Beräkningar!B:B=B24)*('Priser SE2'!G:G=A24)*1),0) | D24: =IFERROR(AVERAGEIFS(Beräkningar!E:E,Beräkningar!B:B,B24,'Priser SE2'!G:G,A24),0) | E24: 42.5 | F24: =IFERROR(MAXIFS(Beräkningar!E:E,Beräkningar!B:B,B24,'Priser SE2'!G:G,A24),0) | G24: =IFERROR(SUMIFS(Beräkningar!F:F,Beräkningar!B:B,B24,'Priser SE2'!G:G,A24),0) | H24: =IFERROR(IF(C24>0,SUMIFS(Beräkningar!G:G,Beräkningar!B:B,B24,'Priser SE2'!G:G,A24)/C24,0),0) | I24: =IFERROR(SUMIFS(Beräkningar!J:J,Beräkningar!B:B,B24,'Priser SE2'!G:G,A24),0) | J24: =IFERROR(IF(C24>0,SUMIFS(Beräkningar!K:K,Beräkningar!B:B,B24,'Priser SE2'!G:G,A24)/C24,0),0)
A25: 2022-04 | B25: SE3 | C25: =IFERROR(SUMPRODUCT((Beräkningar!B:B=B25)*('Priser SE3'!G:G=A25)*1),0) | D25: =IFERROR(AVERAGEIFS(Beräkningar!E:E,Beräkningar!B:B,B25,'Priser SE3'!G:G,A25),0) | E25: 126.86 | F25: =IFERROR(MAXIFS(Beräkningar!E:E,Beräkningar!B:B,B25,'Priser SE3'!G:G,A25),0) | G25: =IFERROR(SUMIFS(Beräkningar!F:F,Beräkningar!B:B,B25,'Priser SE3'!G:G,A25),0) | H25: =IFERROR(IF(C25>0,SUMIFS(Beräkningar!G:G,Beräkningar!B:B,B25,'Priser SE3'!G:G,A25)/C25,0),0) | I25: =IFERROR(SUMIFS(Beräkningar!J:J,Beräkningar!B:B,B25,'Priser SE3'!G:G,A25),0) | J25: =IFERROR(IF(C25>0,SUMIFS(Beräkningar!K:K,Beräkningar!B:B,B25,'Priser SE3'!G:G,A25)/C25,0),0)
A26: 2022-04 | B26: SE4 | C26: =IFERROR(SUMPRODUCT((Beräkningar!B:B=B26)*('Priser SE4'!G:G=A26)*1),0) | D26: =IFERROR(AVERAGEIFS(Beräkningar!E:E,Beräkningar!B:B,B26,'Priser SE4'!G:G,A26),0) | E26: 121.8 | F26: =IFERROR(MAXIFS(Beräkningar!E:E,Beräkningar!B:B,B26,'Priser SE4'!G:G,A26),0) | G26: =IFERROR(SUMIFS(Beräkningar!F:F,Beräkningar!B:B,B26,'Priser SE4'!G:G,A26),0) | H26: =IFERROR(IF(C26>0,SUMIFS(Beräkningar!G:G,Beräkningar!B:B,B26,'Priser SE4'!G:G,A26)/C26,0),0) | I26: =IFERROR(SUMIFS(Beräkningar!J:J,Beräkningar!B:B,B26,'Priser SE4'!G:G,A26),0) | J26: =IFERROR(IF(C26>0,SUMIFS(Beräkningar!K:K,Beräkningar!B:B,B26,'Priser SE4'!G:G,A26)/C26,0),0)
A27: 2022-05 | B27: SE1 | C27: =IFERROR(SUMPRODUCT((Beräkningar!B:B=B27)*('Priser SE1'!G:G=A27)*1),0) | D27: =IFERROR(AVERAGEIFS(Beräkningar!E:E,Beräkningar!B:B,B27,'Priser SE1'!G:G,A27),0) | E27: 54.31 | F27: =IFERROR(MAXIFS(Beräkningar!E:E,Beräkningar!B:B,B27,'Priser SE1'!G:G,A27),0) | G27: =IFERROR(SUMIFS(Beräkningar!F:F,Beräkningar!B:B,B27,'Priser SE1'!G:G,A27),0) | H27: =IFERROR(IF(C27>0,SUMIFS(Beräkningar!G:G,Beräkningar!B:B,B27,'Priser SE1'!G:G,A27)/C27,0),0) | I27: =IFERROR(SUMIFS(Beräkningar!J:J,Beräkningar!B:B,B27,'Priser SE1'!G:G,A27),0) | J27: =IFERROR(IF(C27>0,SUMIFS(Beräkningar!K:K,Beräkningar!B:B,B27,'Priser SE1'!G:G,A27)/C27,0),0)
A28: 2022-05 | B28: SE2 | C28: =IFERROR(SUMPRODUCT((Beräkningar!B:B=B28)*('Priser SE2'!G:G=A28)*1),0) | D28: =IFERROR(AVERAGEIFS(Beräkningar!E:E,Beräkningar!B:B,B28,'Priser SE2'!G:G,A28),0) | E28: 54.31 | F28: =IFERROR(MAXIFS(Beräkningar!E:E,Beräkningar!B:B,B28,'Priser SE2'!G:G,A28),0) | G28: =IFERROR(SUMIFS(Beräkningar!F:F,Beräkningar!B:B,B28,'Priser SE2'!G:G,A28),0) | H28: =IFERROR(IF(C28>0,SUMIFS(Beräkningar!G:G,Beräkningar!B:B,B28,'Priser SE2'!G:G,A28)/C28,0),0) | I28: =IFERROR(SUMIFS(Beräkningar!J:J,Beräkningar!B:B,B28,'Priser SE2'!G:G,A28),0) | J28: =IFERROR(IF(C28>0,SUMIFS(Beräkningar!K:K,Beräkningar!B:B,B28,'Priser SE2'!G:G,A28)/C28,0),0)
A29: 2022-05 | B29: SE3 | C29: =IFERROR(SUMPRODUCT((Beräkningar!B:B=B29)*('Priser SE3'!G:G=A29)*1),0) | D29: =IFERROR(AVERAGEIFS(Beräkningar!E:E,Beräkningar!B:B,B29,'Priser SE3'!G:G,A29),0) | E29: 171.06 | F29: =IFERROR(MAXIFS(Beräkningar!E:E,Beräkningar!B:B,B29,'Priser SE3'!G:G,A29),0) | G29: =IFERROR(SUMIFS(Beräkningar!F:F,Beräkningar!B:B,B29,'Priser SE3'!G:G,A29),0) | H29: =IFERROR(IF(C29>0,SUMIFS(Beräkningar!G:G,Beräkningar!B:B,B29,'Priser SE3'!G:G,A29)/C29,0),0) | I29: =IFERROR(SUMIFS(Beräkningar!J:J,Beräkningar!B:B,B29,'Priser SE3'!G:G,A29),0) | J29: =IFERROR(IF(C29>0,SUMIFS(Beräkningar!K:K,Beräkningar!B:B,B29,'Priser SE3'!G:G,A29)/C29,0),0)
A30: 2022-05 | B30: SE4 | C30: =IFERROR(SUMPRODUCT((Beräkningar!B:B=B30)*('Priser SE4'!G:G=A30)*1),0) | D30: =IFERROR(AVERAGEIFS(Beräkningar!E:E,Beräkningar!B:B,B30,'Priser SE4'!G:G,A30),0) | E30: 182.91 | F30: =IFERROR(MAXIFS(Beräkningar!E:E,Beräkningar!B:B,B30,'Priser SE4'!G:G,A30),0) | G30: =IFERROR(SUMIFS(Beräkningar!F:F,Beräkningar!B:B,B30,'Priser SE4'!G:G,A30),0) | H30: =IFERROR(IF(C30>0,SUMIFS(Beräkningar!G:G,Beräkningar!B:B,B30,'Priser SE4'!G:G,A30)/C30,0),0) | I30: =IFERROR(SUMIFS(Beräkningar!J:J,Beräkningar!B:B,B30,'Priser SE4'!G:G,A30),0) | J30: =IFERROR(IF(C30>0,SUMIFS(Beräkningar!K:K,Beräkningar!B:B,B30,'Priser SE4'!G:G,A30)/C30,0),0)
A31: 2022-06 | B31: SE1 | C31: =IFERROR(SUMPRODUCT((Beräkningar!B:B=B31)*('Priser SE1'!G:G=A31)*1),0) | D31: =IFERROR(AVERAGEIFS(Beräkningar!E:E,Beräkningar!B:B,B31,'Priser SE1'!G:G,A31),0) | E31: 37.92 | F31: =IFERROR(MAXIFS(Beräkningar!E:E,Beräkningar!B:B,B31,'Priser SE1'!G:G,A31),0) | G31: =IFERROR(SUMIFS(Beräkningar!F:F,Beräkningar!B:B,B31,'Priser SE1'!G:G,A31),0) | H31: =IFERROR(IF(C31>0,SUMIFS(Beräkningar!G:G,Beräkningar!B:B,B31,'Priser SE1'!G:G,A31)/C31,0),0) | I31: =IFERROR(SUMIFS(Beräkningar!J:J,Beräkningar!B:B,B31,'Priser SE1'!G:G,A31),0) | J31: =IFERROR(IF(C31>0,SUMIFS(Beräkningar!K:K,Beräkningar!B:B,B31,'Priser SE1'!G:G,A31)/C31,0),0)
A32: 2022-06 | B32: SE2 | C32: =IFERROR(SUMPRODUCT((Beräkningar!B:B=B32)*('Priser SE2'!G:G=A32)*1),0) | D32: =IFERROR(AVERAGEIFS(Beräkningar!E:E,Beräkningar!B:B,B32,'Priser SE2'!G:G,A32),0) | E32: 37.92 | F32: =IFERROR(MAXIFS(Beräkningar!E:E,Beräkningar!B:B,B32,'Priser SE2'!G:G,A32),0) | G32: =IFERROR(SUMIFS(Beräkningar!F:F,Beräkningar!B:B,B32,'Priser SE2'!G:G,A32),0) | H32: =IFERROR(IF(C32>0,SUMIFS(Beräkningar!G:G,Beräkningar!B:B,B32,'Priser SE2'!G:G,A32)/C32,0),0) | I32: =IFERROR(SUMIFS(Beräkningar!J:J,Beräkningar!B:B,B32,'Priser SE2'!G:G,A32),0) | J32: =IFERROR(IF(C32>0,SUMIFS(Beräkningar!K:K,Beräkningar!B:B,B32,'Priser SE2'!G:G,A32)/C32,0),0)
A33: 2022-06 | B33: SE3 | C33: =IFERROR(SUMPRODUCT((Beräkningar!B:B=B33)*('Priser SE3'!G:G=A33)*1),0) | D33: =IFERROR(AVERAGEIFS(Beräkningar!E:E,Beräkningar!B:B,B33,'Priser SE3'!G:G,A33),0) | E33: 195.51 | F33: =IFERROR(MAXIFS(Beräkningar!E:E,Beräkningar!B:B,B33,'Priser SE3'!G:G,A33),0) | G33: =IFERROR(SUMIFS(Beräkningar!F:F,Beräkningar!B:B,B33,'Priser SE3'!G:G,A33),0) | H33: =IFERROR(IF(C33>0,SUMIFS(Beräkningar!G:G,Beräkningar!B:B,B33,'Priser SE3'!G:G,A33)/C33,0),0) | I33: =IFERROR(SUMIFS(Beräkningar!J:J,Beräkningar!B:B,B33,'Priser SE3'!G:G,A33),0) | J33: =IFERROR(IF(C33>0,SUMIFS(Beräkningar!K:K,Beräkningar!B:B,B33,'Priser SE3'!G:G,A33)/C33,0),0)
A34: 2022-06 | B34: SE4 | C34: =IFERROR(SUMPRODUCT((Beräkningar!B:B=B34)*('Priser SE4'!G:G=A34)*1),0) | D34: =IFERROR(AVERAGEIFS(Beräkningar!E:E,Beräkningar!B:B,B34,'Priser SE4'!G:G,A34),0) | E34: 202.19 | F34: =IFERROR(MAXIFS(Beräkningar!E:E,Beräkningar!B:B,B34,'Priser SE4'!G:G,A34),0) | G34: =IFERROR(SUMIFS(Beräkningar!F:F,Beräkningar!B:B,B34,'Priser SE4'!G:G,A34),0) | H34: =IFERROR(IF(C34>0,SUMIFS(Beräkningar!G:G,Beräkningar!B:B,B34,'Priser SE4'!G:G,A34)/C34,0),0) | I34: =IFERROR(SUMIFS(Beräkningar!J:J,Beräkningar!B:B,B34,'Priser SE4'!G:G,A34),0) | J34: =IFERROR(IF(C34>0,SUMIFS(Beräkningar!K:K,Beräkningar!B:B,B34,'Priser SE4'!G:G,A34)/C34,0),0)
A35: 2022-07 | B35: SE1 | C35: =IFERROR(SUMPRODUCT((Beräkningar!B:B=B35)*('Priser SE1'!G:G=A35)*1),0) | D35: =IFERROR(AVERAGEIFS(Beräkningar!E:E,Beräkningar!B:B,B35,'Priser SE1'!G:G,A35),0) | E35: 18.03 | F35: =IFERROR(MAXIFS(Beräkningar!E:E,Beräkningar!B:B,B35,'Priser SE1'!G:G,A35),0) | G35: =IFERROR(SUMIFS(Beräkningar!F:F,Beräkningar!B:B,B35,'Priser SE1'!G:G,A35),0) | H35: =IFERROR(IF(C35>0,SUMIFS(Beräkningar!G:G,Beräkningar!B:B,B35,'Priser SE1'!G:G,A35)/C35,0),0) | I35: =IFERROR(SUMIFS(Beräkningar!J:J,Beräkningar!B:B,B35,'Priser SE1'!G:G,A35),0) | J35: =IFERROR(IF(C35>0,SUMIFS(Beräkningar!K:K,Beräkningar!B:B,B35,'Priser SE1'!G:G,A35)/C35,0),0)
A36: 2022-07 | B36: SE2 | C36: =IFERROR(SUMPRODUCT((Beräkningar!B:B=B36)*('Priser SE2'!G:G=A36)*1),0) | D36: =IFERROR(AVERAGEIFS(Beräkningar!E:E,Beräkningar!B:B,B36,'Priser SE2'!G:G,A36),0) | E36: 18.03 | F36: =IFERROR(MAXIFS(Beräkningar!E:E,Beräkningar!B:B,B36,'Priser SE2'!G:G,A36),0) | G36: =IFERROR(SUMIFS(Beräkningar!F:F,Beräkningar!B:B,B36,'Priser SE2'!G:G,A36),0) | H36: =IFERROR(IF(C36>0,SUMIFS(Beräkningar!G:G,Beräkningar!B:B,B36,'Priser SE2'!G:G,A36)/C36,0),0) | I36: =IFERROR(SUMIFS(Beräkningar!J:J,Beräkningar!B:B,B36,'Priser SE2'!G:G,A36),0) | J36: =IFERROR(IF(C36>0,SUMIFS(Beräkningar!K:K,Beräkningar!B:B,B36,'Priser SE2'!G:G,A36)/C36,0),0)
A37: 2022-07 | B37: SE3 | C37: =IFERROR(SUMPRODUCT((Beräkningar!B:B=B37)*('Priser SE3'!G:G=A37)*1),0) | D37: =IFERROR(AVERAGEIFS(Beräkningar!E:E,Beräkningar!B:B,B37,'Priser SE3'!G:G,A37),0) | E37: 168.35 | F37: =IFERROR(MAXIFS(Beräkningar!E:E,Beräkningar!B:B,B37,'Priser SE3'!G:G,A37),0) | G37: =IFERROR(SUMIFS(Beräkningar!F:F,Beräkningar!B:B,B37,'Priser SE3'!G:G,A37),0) | H37: =IFERROR(IF(C37>0,SUMIFS(Beräkningar!G:G,Beräkningar!B:B,B37,'Priser SE3'!G:G,A37)/C37,0),0) | I37: =IFERROR(SUMIFS(Beräkningar!J:J,Beräkningar!B:B,B37,'Priser SE3'!G:G,A37),0) | J37: =IFERROR(IF(C37>0,SUMIFS(Beräkningar!K:K,Beräkningar!B:B,B37,'Priser SE3'!G:G,A37)/C37,0),0)
A38: 2022-07 | B38: SE4 | C38: =IFERROR(SUMPRODUCT((Beräkningar!B:B=B38)*('Priser SE4'!G:G=A38)*1),0) | D38: =IFERROR(AVERAGEIFS(Beräkningar!E:E,Beräkningar!B:B,B38,'Priser SE4'!G:G,A38),0) | E38: 189.73 | F38: =IFERROR(MAXIFS(Beräkningar!E:E,Beräkningar!B:B,B38,'Priser SE4'!G:G,A38),0) | G38: =IFERROR(SUMIFS(Beräkningar!F:F,Beräkningar!B:B,B38,'Priser SE4'!G:G,A38),0) | H38: =IFERROR(IF(C38>0,SUMIFS(Beräkningar!G:G,Beräkningar!B:B,B38,'Priser SE4'!G:G,A38)/C38,0),0) | I38: =IFERROR(SUMIFS(Beräkningar!J:J,Beräkningar!B:B,B38,'Priser SE4'!G:G,A38),0) | J38: =IFERROR(IF(C38>0,SUMIFS(Beräkningar!K:K,Beräkningar!B:B,B38,'Priser SE4'!G:G,A38)/C38,0),0)
A39: 2022-08 | B39: SE1 | C39: =IFERROR(SUMPRODUCT((Beräkningar!B:B=B39)*('Priser SE1'!G:G=A39)*1),0) | D39: =IFERROR(AVERAGEIFS(Beräkningar!E:E,Beräkningar!B:B,B39,'Priser SE1'!G:G,A39),0) | E39: 14.57 | F39: =IFERROR(MAXIFS(Beräkningar!E:E,Beräkningar!B:B,B39,'Priser SE1'!G:G,A39),0) | G39: =IFERROR(SUMIFS(Beräkningar!F:F,Beräkningar!B:B,B39,'Priser SE1'!G:G,A39),0) | H39: =IFERROR(IF(C39>0,SUMIFS(Beräkningar!G:G,Beräkningar!B:B,B39,'Priser SE1'!G:G,A39)/C39,0),0) | I39: =IFERROR(SUMIFS(Beräkningar!J:J,Beräkningar!B:B,B39,'Priser SE1'!G:G,A39),0) | J39: =IFERROR(IF(C39>0,SUMIFS(Beräkningar!K:K,Beräkningar!B:B,B39,'Priser SE1'!G:G,A39)/C39,0),0)
A40: 2022-08 | B40: SE2 | C40: =IFERROR(SUMPRODUCT((Beräkningar!B:B=B40)*('Priser SE2'!G:G=A40)*1),0) | D40: =IFERROR(AVERAGEIFS(Beräkningar!E:E,Beräkningar!B:B,B40,'Priser SE2'!G:G,A40),0) | E40: 43.92 | F40: =IFERROR(MAXIFS(Beräkningar!E:E,Beräkningar!B:B,B40,'Priser SE2'!G:G,A40),0) | G40: =IFERROR(SUMIFS(Beräkningar!F:F,Beräkningar!B:B,B40,'Priser SE2'!G:G,A40),0) | H40: =IFERROR(IF(C40>0,SUMIFS(Beräkningar!G:G,Beräkningar!B:B,B40,'Priser SE2'!G:G,A40)/C40,0),0) | I40: =IFERROR(SUMIFS(Beräkningar!J:J,Beräkningar!B:B,B40,'Priser SE2'!G:G,A40),0) | J40: =IFERROR(IF(C40>0,SUMIFS(Beräkningar!K:K,Beräkningar!B:B,B40,'Priser SE2'!G:G,A40)/C40,0),0)
...

Sheet Årssammanfattning
A1: År | B1: Zon | C1: Antal dagar | D1: Avg Spread | E1: Median Spread | F1: Max Spread | G1: Revenue 1C | H1: Profitable 1C % | I1: Revenue 2C | J1: Profitable 2C %
A2: 2021 | B2: SE1 | C2: =IFERROR(COUNTIFS('Priser SE1'!H:H,A2),0) | D2: =IFERROR(AVERAGEIFS(Beräkningar!E:E,Beräkningar!B:B,B2,Beräkningar!L:L,A2),0) | E2: 14.01 | F2: =IFERROR(MAXIFS(Beräkningar!E:E,Beräkningar!B:B,B2,Beräkningar!L:L,A2),0) | G2: =IFERROR(SUMIFS(Beräkningar!F:F,Beräkningar!B:B,B2,Beräkningar!L:L,A2),0) | H2: =IFERROR(SUMIFS(Beräkningar!G:G,Beräkningar!B:B,B2,Beräkningar!L:L,A2)/C2,0) | I2: =IFERROR(SUMIFS(Beräkningar!J:J,Beräkningar!B:B,B2,Beräkningar!L:L,A2),0) | J2: =IFERROR(SUMIFS(Beräkningar!K:K,Beräkningar!B:B,B2,Beräkningar!L:L,A2)/C2,0)
A3: 2022 | B3: SE1 | C3: =IFERROR(COUNTIFS('Priser SE1'!H:H,A3),0) | D3: =IFERROR(AVERAGEIFS(Beräkningar!E:E,Beräkningar!B:B,B3,Beräkningar!L:L,A3),0) | E3: 30.77 | F3: =IFERROR(MAXIFS(Beräkningar!E:E,Beräkningar!B:B,B3,Beräkningar!L:L,A3),0) | G3: =IFERROR(SUMIFS(Beräkningar!F:F,Beräkningar!B:B,B3,Beräkningar!L:L,A3),0) | H3: =IFERROR(SUMIFS(Beräkningar!G:G,Beräkningar!B:B,B3,Beräkningar!L:L,A3)/C3,0) | I3: =IFERROR(SUMIFS(Beräkningar!J:J,Beräkningar!B:B,B3,Beräkningar!L:L,A3),0) | J3: =IFERROR(SUMIFS(Beräkningar!K:K,Beräkningar!B:B,B3,Beräkningar!L:L,A3)/C3,0)
A4: 2023 | B4: SE1 | C4: =IFERROR(COUNTIFS('Priser SE1'!H:H,A4),0) | D4: =IFERROR(AVERAGEIFS(Beräkningar!E:E,Beräkningar!B:B,B4,Beräkningar!L:L,A4),0) | E4: 24.81 | F4: =IFERROR(MAXIFS(Beräkningar!E:E,Beräkningar!B:B,B4,Beräkningar!L:L,A4),0) | G4: =IFERROR(SUMIFS(Beräkningar!F:F,Beräkningar!B:B,B4,Beräkningar!L:L,A4),0) | H4: =IFERROR(SUMIFS(Beräkningar!G:G,Beräkningar!B:B,B4,Beräkningar!L:L,A4)/C4,0) | I4: =IFERROR(SUMIFS(Beräkningar!J:J,Beräkningar!B:B,B4,Beräkningar!L:L,A4),0) | J4: =IFERROR(SUMIFS(Beräkningar!K:K,Beräkningar!B:B,B4,Beräkningar!L:L,A4)/C4,0)
A5: 2024 | B5: SE1 | C5: =IFERROR(COUNTIFS('Priser SE1'!H:H,A5),0) | D5: =IFERROR(AVERAGEIFS(Beräkningar!E:E,Beräkningar!B:B,B5,Beräkningar!L:L,A5),0) | E5: 20.08 | F5: =IFERROR(MAXIFS(Beräkningar!E:E,Beräkningar!B:B,B5,Beräkningar!L:L,A5),0) | G5: =IFERROR(SUMIFS(Beräkningar!F:F,Beräkningar!B:B,B5,Beräkningar!L:L,A5),0) | H5: =IFERROR(SUMIFS(Beräkningar!G:G,Beräkningar!B:B,B5,Beräkningar!L:L,A5)/C5,0) | I5: =IFERROR(SUMIFS(Beräkningar!J:J,Beräkningar!B:B,B5,Beräkningar!L:L,A5),0) | J5: =IFERROR(SUMIFS(Beräkningar!K:K,Beräkningar!B:B,B5,Beräkningar!L:L,A5)/C5,0)
A6: 2025 | B6: SE1 | C6: =IFERROR(COUNTIFS('Priser SE1'!H:H,A6),0) | D6: =IFERROR(AVERAGEIFS(Beräkningar!E:E,Beräkningar!B:B,B6,Beräkningar!L:L,A6),0) | E6: 13.19 | F6: =IFERROR(MAXIFS(Beräkningar!E:E,Beräkningar!B:B,B6,Beräkningar!L:L,A6),0) | G6: =IFERROR(SUMIFS(Beräkningar!F:F,Beräkningar!B:B,B6,Beräkningar!L:L,A6),0) | H6: =IFERROR(SUMIFS(Beräkningar!G:G,Beräkningar!B:B,B6,Beräkningar!L:L,A6)/C6,0) | I6: =IFERROR(SUMIFS(Beräkningar!J:J,Beräkningar!B:B,B6,Beräkningar!L:L,A6),0) | J6: =IFERROR(SUMIFS(Beräkningar!K:K,Beräkningar!B:B,B6,Beräkningar!L:L,A6)/C6,0)
A7: 2026 | B7: SE1 | C7: =IFERROR(COUNTIFS('Priser SE1'!H:H,A7),0) | D7: =IFERROR(AVERAGEIFS(Beräkningar!E:E,Beräkningar!B:B,B7,Beräkningar!L:L,A7),0) | E7: 43.53 | F7: =IFERROR(MAXIFS(Beräkningar!E:E,Beräkningar!B:B,B7,Beräkningar!L:L,A7),0) | G7: =IFERROR(SUMIFS(Beräkningar!F:F,Beräkningar!B:B,B7,Beräkningar!L:L,A7),0) | H7: =IFERROR(SUMIFS(Beräkningar!G:G,Beräkningar!B:B,B7,Beräkningar!L:L,A7)/C7,0) | I7: =IFERROR(SUMIFS(Beräkningar!J:J,Beräkningar!B:B,B7,Beräkningar!L:L,A7),0) | J7: =IFERROR(SUMIFS(Beräkningar!K:K,Beräkningar!B:B,B7,Beräkningar!L:L,A7)/C7,0)
A8: 2021 | B8: SE2 | C8: =IFERROR(COUNTIFS('Priser SE2'!H:H,A8),0) | D8: =IFERROR(AVERAGEIFS(Beräkningar!E:E,Beräkningar!B:B,B8,Beräkningar!L:L,A8),0) | E8: 14.01 | F8: =IFERROR(MAXIFS(Beräkningar!E:E,Beräkningar!B:B,B8,Beräkningar!L:L,A8),0) | G8: =IFERROR(SUMIFS(Beräkningar!F:F,Beräkningar!B:B,B8,Beräkningar!L:L,A8),0) | H8: =IFERROR(SUMIFS(Beräkningar!G:G,Beräkningar!B:B,B8,Beräkningar!L:L,A8)/C8,0) | I8: =IFERROR(SUMIFS(Beräkningar!J:J,Beräkningar!B:B,B8,Beräkningar!L:L,A8),0) | J8: =IFERROR(SUMIFS(Beräkningar!K:K,Beräkningar!B:B,B8,Beräkningar!L:L,A8)/C8,0)
A9: 2022 | B9: SE2 | C9: =IFERROR(COUNTIFS('Priser SE2'!H:H,A9),0) | D9: =IFERROR(AVERAGEIFS(Beräkningar!E:E,Beräkningar!B:B,B9,Beräkningar!L:L,A9),0) | E9: 32.63 | F9: =IFERROR(MAXIFS(Beräkningar!E:E,Beräkningar!B:B,B9,Beräkningar!L:L,A9),0) | G9: =IFERROR(SUMIFS(Beräkningar!F:F,Beräkningar!B:B,B9,Beräkningar!L:L,A9),0) | H9: =IFERROR(SUMIFS(Beräkningar!G:G,Beräkningar!B:B,B9,Beräkningar!L:L,A9)/C9,0) | I9: =IFERROR(SUMIFS(Beräkningar!J:J,Beräkningar!B:B,B9,Beräkningar!L:L,A9),0) | J9: =IFERROR(SUMIFS(Beräkningar!K:K,Beräkningar!B:B,B9,Beräkningar!L:L,A9)/C9,0)
A10: 2023 | B10: SE2 | C10: =IFERROR(COUNTIFS('Priser SE2'!H:H,A10),0) | D10: =IFERROR(AVERAGEIFS(Beräkningar!E:E,Beräkningar!B:B,B10,Beräkningar!L:L,A10),0) | E10: 24.81 | F10: =IFERROR(MAXIFS(Beräkningar!E:E,Beräkningar!B:B,B10,Beräkningar!L:L,A10),0) | G10: =IFERROR(SUMIFS(Beräkningar!F:F,Beräkningar!B:B,B10,Beräkningar!L:L,A10),0) | H10: =IFERROR(SUMIFS(Beräkningar!G:G,Beräkningar!B:B,B10,Beräkningar!L:L,A10)/C10,0) | I10: =IFERROR(SUMIFS(Beräkningar!J:J,Beräkningar!B:B,B10,Beräkningar!L:L,A10),0) | J10: =IFERROR(SUMIFS(Beräkningar!K:K,Beräkningar!B:B,B10,Beräkningar!L:L,A10)/C10,0)
A11: 2024 | B11: SE2 | C11: =IFERROR(COUNTIFS('Priser SE2'!H:H,A11),0) | D11: =IFERROR(AVERAGEIFS(Beräkningar!E:E,Beräkningar!B:B,B11,Beräkningar!L:L,A11),0) | E11: 20.73 | F11: =IFERROR(MAXIFS(Beräkningar!E:E,Beräkningar!B:B,B11,Beräkningar!L:L,A11),0) | G11: =IFERROR(SUMIFS(Beräkningar!F:F,Beräkningar!B:B,B11,Beräkningar!L:L,A11),0) | H11: =IFERROR(SUMIFS(Beräkningar!G:G,Beräkningar!B:B,B11,Beräkningar!L:L,A11)/C11,0) | I11: =IFERROR(SUMIFS(Beräkningar!J:J,Beräkningar!B:B,B11,Beräkningar!L:L,A11),0) | J11: =IFERROR(SUMIFS(Beräkningar!K:K,Beräkningar!B:B,B11,Beräkningar!L:L,A11)/C11,0)
A12: 2025 | B12: SE2 | C12: =IFERROR(COUNTIFS('Priser SE2'!H:H,A12),0) | D12: =IFERROR(AVERAGEIFS(Beräkningar!E:E,Beräkningar!B:B,B12,Beräkningar!L:L,A12),0) | E12: 15.13 | F12: =IFERROR(MAXIFS(Beräkningar!E:E,Beräkningar!B:B,B12,Beräkningar!L:L,A12),0) | G12: =IFERROR(SUMIFS(Beräkningar!F:F,Beräkningar!B:B,B12,Beräkningar!L:L,A12),0) | H12: =IFERROR(SUMIFS(Beräkningar!G:G,Beräkningar!B:B,B12,Beräkningar!L:L,A12)/C12,0) | I12: =IFERROR(SUMIFS(Beräkningar!J:J,Beräkningar!B:B,B12,Beräkningar!L:L,A12),0) | J12: =IFERROR(SUMIFS(Beräkningar!K:K,Beräkningar!B:B,B12,Beräkningar!L:L,A12)/C12,0)
A13: 2026 | B13: SE2 | C13: =IFERROR(COUNTIFS('Priser SE2'!H:H,A13),0) | D13: =IFERROR(AVERAGEIFS(Beräkningar!E:E,Beräkningar!B:B,B13,Beräkningar!L:L,A13),0) | E13: 43.53 | F13: =IFERROR(MAXIFS(Beräkningar!E:E,Beräkningar!B:B,B13,Beräkningar!L:L,A13),0) | G13: =IFERROR(SUMIFS(Beräkningar!F:F,Beräkningar!B:B,B13,Beräkningar!L:L,A13),0) | H13: =IFERROR(SUMIFS(Beräkningar!G:G,Beräkningar!B:B,B13,Beräkningar!L:L,A13)/C13,0) | I13: =IFERROR(SUMIFS(Beräkningar!J:J,Beräkningar!B:B,B13,Beräkningar!L:L,A13),0) | J13: =IFERROR(SUMIFS(Beräkningar!K:K,Beräkningar!B:B,B13,Beräkningar!L:L,A13)/C13,0)
A14: 2021 | B14: SE3 | C14: =IFERROR(COUNTIFS('Priser SE3'!H:H,A14),0) | D14: =IFERROR(AVERAGEIFS(Beräkningar!E:E,Beräkningar!B:B,B14,Beräkningar!L:L,A14),0) | E14: 136.96 | F14: =IFERROR(MAXIFS(Beräkningar!E:E,Beräkningar!B:B,B14,Beräkningar!L:L,A14),0) | G14: =IFERROR(SUMIFS(Beräkningar!F:F,Beräkningar!B:B,B14,Beräkningar!L:L,A14),0) | H14: =IFERROR(SUMIFS(Beräkningar!G:G,Beräkningar!B:B,B14,Beräkningar!L:L,A14)/C14,0) | I14: =IFERROR(SUMIFS(Beräkningar!J:J,Beräkningar!B:B,B14,Beräkningar!L:L,A14),0) | J14: =IFERROR(SUMIFS(Beräkningar!K:K,Beräkningar!B:B,B14,Beräkningar!L:L,A14)/C14,0)
A15: 2022 | B15: SE3 | C15: =IFERROR(COUNTIFS('Priser SE3'!H:H,A15),0) | D15: =IFERROR(AVERAGEIFS(Beräkningar!E:E,Beräkningar!B:B,B15,Beräkningar!L:L,A15),0) | E15: 156.8 | F15: =IFERROR(MAXIFS(Beräkningar!E:E,Beräkningar!B:B,B15,Beräkningar!L:L,A15),0) | G15: =IFERROR(SUMIFS(Beräkningar!F:F,Beräkningar!B:B,B15,Beräkningar!L:L,A15),0) | H15: =IFERROR(SUMIFS(Beräkningar!G:G,Beräkningar!B:B,B15,Beräkningar!L:L,A15)/C15,0) | I15: =IFERROR(SUMIFS(Beräkningar!J:J,Beräkningar!B:B,B15,Beräkningar!L:L,A15),0) | J15: =IFERROR(SUMIFS(Beräkningar!K:K,Beräkningar!B:B,B15,Beräkningar!L:L,A15)/C15,0)
A16: 2023 | B16: SE3 | C16: =IFERROR(COUNTIFS('Priser SE3'!H:H,A16),0) | D16: =IFERROR(AVERAGEIFS(Beräkningar!E:E,Beräkningar!B:B,B16,Beräkningar!L:L,A16),0) | E16: 55.2 | F16: =IFERROR(MAXIFS(Beräkningar!E:E,Beräkningar!B:B,B16,Beräkningar!L:L,A16),0) | G16: =IFERROR(SUMIFS(Beräkningar!F:F,Beräkningar!B:B,B16,Beräkningar!L:L,A16),0) | H16: =IFERROR(SUMIFS(Beräkningar!G:G,Beräkningar!B:B,B16,Beräkningar!L:L,A16)/C16,0) | I16: =IFERROR(SUMIFS(Beräkningar!J:J,Beräkningar!B:B,B16,Beräkningar!L:L,A16),0) | J16: =IFERROR(SUMIFS(Beräkningar!K:K,Beräkningar!B:B,B16,Beräkningar!L:L,A16)/C16,0)
