Workbook

Sheet Parametrar
A1: BASELOAD PPA VALIDERING
A3: REDIGERBARA PARAMETRAR
A4: Baseload (MW) | B4: 0.23147687
A5: Batterieffektivitet | B5: 0.9
A6: Sol installerat (MW) | B6: 0.4
A7: Vind installerat (MW) | B7: 1.6
A9: FASTA PARAMETRAR
A10: Zon | B10: SE3
A11: År | B11: 2024
A12: Solprofil | B12: south_lundby
A13: Timmar | B13: 8784
A15: BERÄKNADE NYCKELTAL
A16: Total produktion (MWh) | B16: =SUM(Timberäkning!D:D)
A17: Baseload-behov (MWh) | B17: =B4*B13
A18: Total deficit (MWh) | B18: =SUM(Timberäkning!G:G)
A19: Total surplus (MWh) | B19: =SUM(Timberäkning!H:H)
A20: Deficit-timmar | B20: =COUNTIF(Timberäkning!G:G,">0")
A21: Surplus-timmar | B21: =COUNTIF(Timberäkning!H:H,">0")
A22: Max deficit (MW) | B22: =MAX(Timberäkning!G:G)
A23: Max batteribehov (MWh) | B23: =MAX(Timberäkning!K:K)
A24: Batteriduration (h) | B24: =B23/B4

Sheet Sol Profil
A1: Timestamp | B1: Månad | C1: Dag | D1: Timme | E1: Norm (0-1) | F1: MW
A2: 2024-01-01 00:00 | B2: 1 | C2: 1 | D2: 0 | E2: 0 | F2: =E2*Parametrar!$B$6
A3: 2024-01-01 01:00 | B3: 1 | C3: 1 | D3: 1 | E3: 0 | F3: =E3*Parametrar!$B$6
A4: 2024-01-01 02:00 | B4: 1 | C4: 1 | D4: 2 | E4: 0 | F4: =E4*Parametrar!$B$6
A5: 2024-01-01 03:00 | B5: 1 | C5: 1 | D5: 3 | E5: 0 | F5: =E5*Parametrar!$B$6
A6: 2024-01-01 04:00 | B6: 1 | C6: 1 | D6: 4 | E6: 0 | F6: =E6*Parametrar!$B$6
A7: 2024-01-01 05:00 | B7: 1 | C7: 1 | D7: 5 | E7: 0 | F7: =E7*Parametrar!$B$6
A8: 2024-01-01 06:00 | B8: 1 | C8: 1 | D8: 6 | E8: 0 | F8: =E8*Parametrar!$B$6
A9: 2024-01-01 07:00 | B9: 1 | C9: 1 | D9: 7 | E9: 0 | F9: =E9*Parametrar!$B$6
A10: 2024-01-01 08:00 | B10: 1 | C10: 1 | D10: 8 | E10: 0 | F10: =E10*Parametrar!$B$6
A11: 2024-01-01 09:00 | B11: 1 | C11: 1 | D11: 9 | E11: 0.030882 | F11: =E11*Parametrar!$B$6
A12: 2024-01-01 10:00 | B12: 1 | C12: 1 | D12: 10 | E12: 0.119721 | F12: =E12*Parametrar!$B$6
A13: 2024-01-01 11:00 | B13: 1 | C13: 1 | D13: 11 | E13: 0.180765 | F13: =E13*Parametrar!$B$6
... A8785: 2024-12-31 23:00 | B8785: 12 | C8785: 31 | D8785: 23 | E8785: 0 | F8785: =E8785*Parametrar!$B$6

Sheet Vind Profil
A1: Timestamp | B1: Månad | C1: Dag | D1: Timme | E1: CF (0-1) | F1: MW
A2: 2024-01-01 00:00 | B2: 1 | C2: 1 | D2: 0 | E2: 0.46996168 | F2: =E2*Parametrar!$B$7
A3: 2024-01-01 01:00 | B3: 1 | C3: 1 | D3: 1 | E3: 0.44086907 | F3: =E3*Parametrar!$B$7
A4: 2024-01-01 02:00 | B4: 1 | C4: 1 | D4: 2 | E4: 0.43093436 | F4: =E4*Parametrar!$B$7
A5: 2024-01-01 03:00 | B5: 1 | C5: 1 | D5: 3 | E5: 0.4197084 | F5: =E5*Parametrar!$B$7
A6: 2024-01-01 04:00 | B6: 1 | C6: 1 | D6: 4 | E6: 0.41030074 | F6: =E6*Parametrar!$B$7
A7: 2024-01-01 05:00 | B7: 1 | C7: 1 | D7: 5 | E7: 0.40376544 | F7: =E7*Parametrar!$B$7
A8: 2024-01-01 06:00 | B8: 1 | C8: 1 | D8: 6 | E8: 0.39838963 | F8: =E8*Parametrar!$B$7
A9: 2024-01-01 07:00 | B9: 1 | C9: 1 | D9: 7 | E9: 0.39053673 | F9: =E9*Parametrar!$B$7
A10: 2024-01-01 08:00 | B10: 1 | C10: 1 | D10: 8 | E10: 0.38365886 | F10: =E10*Parametrar!$B$7
A11: 2024-01-01 09:00 | B11: 1 | C11: 1 | D11: 9 | E11: 0.37946889 | F11: =E11*Parametrar!$B$7
A12: 2024-01-01 10:00 | B12: 1 | C12: 1 | D12: 10 | E12: 0.37490999 | F12: =E12*Parametrar!$B$7
A13: 2024-01-01 11:00 | B13: 1 | C13: 1 | D13: 11 | E13: 0.36505434 | F13: =E13*Parametrar!$B$7
... A8785: 2024-12-31 23:00 | B8785: 12 | C8785: 31 | D8785: 23 | E8785: 0.46408518 | F8785: =E8785*Parametrar!$B$7

Sheet Timberäkning
A1: Timestamp | B1: Sol (MW) | C1: Vind (MW) | D1: Total (MW) | E1: Baseload (MW) | F1: Diff (MW) | G1: Deficit (MW) | H1: Surplus (MW) | I1: Net Flow (MWh) | J1: Cum Sum | K1: SOC (MWh)
A2: 2024-01-01 00:00 | B2: ='Sol Profil'!F2 | C2: ='Vind Profil'!F2 | D2: =B2+C2 | E2: =Parametrar!$B$4 | F2: =D2-E2 | G2: =MAX(0,-F2) | H2: =MAX(0,F2) | I2: =IF(F2>0,H2*Parametrar!$B$5,-G2) | J2: =I2 | K2: =MAX($J$2:J2)-J2
A3: 2024-01-01 01:00 | B3: ='Sol Profil'!F3 | C3: ='Vind Profil'!F3 | D3: =B3+C3 | E3: =Parametrar!$B$4 | F3: =D3-E3 | G3: =MAX(0,-F3) | H3: =MAX(0,F3) | I3: =IF(F3>0,H3*Parametrar!$B$5,-G3) | J3: =J2+I3 | K3: =MAX($J$2:J3)-J3
A4: 2024-01-01 02:00 | B4: ='Sol Profil'!F4 | C4: ='Vind Profil'!F4 | D4: =B4+C4 | E4: =Parametrar!$B$4 | F4: =D4-E4 | G4: =MAX(0,-F4) | H4: =MAX(0,F4) | I4: =IF(F4>0,H4*Parametrar!$B$5,-G4) | J4: =J3+I4 | K4: =MAX($J$2:J4)-J4
A5: 2024-01-01 03:00 | B5: ='Sol Profil'!F5 | C5: ='Vind Profil'!F5 | D5: =B5+C5 | E5: =Parametrar!$B$4 | F5: =D5-E5 | G5: =MAX(0,-F5) | H5: =MAX(0,F5) | I5: =IF(F5>0,H5*Parametrar!$B$5,-G5) | J5: =J4+I5 | K5: =MAX($J$2:J5)-J5
A6: 2024-01-01 04:00 | B6: ='Sol Profil'!F6 | C6: ='Vind Profil'!F6 | D6: =B6+C6 | E6: =Parametrar!$B$4 | F6: =D6-E6 | G6: =MAX(0,-F6) | H6: =MAX(0,F6) | I6: =IF(F6>0,H6*Parametrar!$B$5,-G6) | J6: =J5+I6 | K6: =MAX($J$2:J6)-J6
A7: 2024-01-01 05:00 | B7: ='Sol Profil'!F7 | C7: ='Vind Profil'!F7 | D7: =B7+C7 | E7: =Parametrar!$B$4 | F7: =D7-E7 | G7: =MAX(0,-F7) | H7: =MAX(0,F7) | I7: =IF(F7>0,H7*Parametrar!$B$5,-G7) | J7: =J6+I7 | K7: =MAX($J$2:J7)-J7
A8: 2024-01-01 06:00 | B8: ='Sol Profil'!F8 | C8: ='Vind Profil'!F8 | D8: =B8+C8 | E8: =Parametrar!$B$4 | F8: =D8-E8 | G8: =MAX(0,-F8) | H8: =MAX(0,F8) | I8: =IF(F8>0,H8*Parametrar!$B$5,-G8) | J8: =J7+I8 | K8: =MAX($J$2:J8)-J8
A9: 2024-01-01 07:00 | B9: ='Sol Profil'!F9 | C9: ='Vind Profil'!F9 | D9: =B9+C9 | E9: =Parametrar!$B$4 | F9: =D9-E9 | G9: =MAX(0,-F9) | H9: =MAX(0,F9) | I9: =IF(F9>0,H9*Parametrar!$B$5,-G9) | J9: =J8+I9 | K9: =MAX($J$2:J9)-J9
A10: 2024-01-01 08:00 | B10: ='Sol Profil'!F10 | C10: ='Vind Profil'!F10 | D10: =B10+C10 | E10: =Parametrar!$B$4 | F10: =D10-E10 | G10: =MAX(0,-F10) | H10: =MAX(0,F10) | I10: =IF(F10>0,H10*Parametrar!$B$5,-G10) | J10: =J9+I10 | K10: =MAX($J$2:J10)-J10
A11: 2024-01-01 09:00 | B11: ='Sol Profil'!F11 | C11: ='Vind Profil'!F11 | D11: =B11+C11 | E11: =Parametrar!$B$4 | F11: =D11-E11 | G11: =MAX(0,-F11) | H11: =MAX(0,F11) | I11: =IF(F11>0,H11*Parametrar!$B$5,-G11) | J11: =J10+I11 | K11: =MAX($J$2:J11)-J11
A12: 2024-01-01 10:00 | B12: ='Sol Profil'!F12 | C12: ='Vind Profil'!F12 | D12: =B12+C12 | E12: =Parametrar!$B$4 | F12: =D12-E12 | G12: =MAX(0,-F12) | H12: =MAX(0,F12) | I12: =IF(F12>0,H12*Parametrar!$B$5,-G12) | J12: =J11+I12 | K12: =MAX($J$2:J12)-J12
A13: 2024-01-01 11:00 | B13: ='Sol Profil'!F13 | C13: ='Vind Profil'!F13 | D13: =B13+C13 | E13: =Parametrar!$B$4 | F13: =D13-E13 | G13: =MAX(0,-F13) | H13: =MAX(0,F13) | I13: =IF(F13>0,H13*Parametrar!$B$5,-G13) | J13: =J12+I13 | K13: =MAX($J$2:J13)-J13
A14: 2024-01-01 12:00 | B14: ='Sol Profil'!F14 | C14: ='Vind Profil'!F14 | D14: =B14+C14 | E14: =Parametrar!$B$4 | F14: =D14-E14 | G14: =MAX(0,-F14) | H14: =MAX(0,F14) | I14: =IF(F14>0,H14*Parametrar!$B$5,-G14) | J14: =J13+I14 | K14: =MAX($J$2:J14)-J14
... A8785: 2024-12-31 23:00 | B8785: ='Sol Profil'!F8785 | C8785: ='Vind Profil'!F8785 | D8785: =B8785+C8785 | E8785: =Parametrar!$B$4 | F8785: =D8785-E8785 | G8785: =MAX(0,-F8785) | H8785: =MAX(0,F8785) | I8785: =IF(F8785>0,H8785*Parametrar!$B$5,-G8785) | J8785: =J8784+I8785 | K8785: =MAX($J$2:J8785)-J8785

Sheet Daglig Summering
A1: Datum | B1: Sol (MWh) | C1: Vind (MWh) | D1: Total (MWh) | E1: Baseload (MWh) | F1: Deficit (MWh) | G1: Surplus (MWh) | H1: Max SOC (MWh) | I1: Status
A2: 2024-01-01 | B2: =SUM(Timberäkning!B2:B25) | C2: =SUM(Timberäkning!C2:C25) | D2: =SUM(Timberäkning!D2:D25) | E2: =Parametrar!$B$4*24 | F2: =SUM(Timberäkning!G2:G25) | G2: =SUM(Timberäkning!H2:H25) | H2: =MAX(Timberäkning!K2:K25) | I2: =IF(F2>0,"DEFICIT","OK")
A3: 2024-01-02 | B3: =SUM(Timberäkning!B26:B49) | C3: =SUM(Timberäkning!C26:C49) | D3: =SUM(Timberäkning!D26:D49) | E3: =Parametrar!$B$4*24 | F3: =SUM(Timberäkning!G26:G49) | G3: =SUM(Timberäkning!H26:H49) | H3: =MAX(Timberäkning!K26:K49) | I3: =IF(F3>0,"DEFICIT","OK")
A4: 2024-01-03 | B4: =SUM(Timberäkning!B50:B73) | C4: =SUM(Timberäkning!C50:C73) | D4: =SUM(Timberäkning!D50:D73) | E4: =Parametrar!$B$4*24 | F4: =SUM(Timberäkning!G50:G73) | G4: =SUM(Timberäkning!H50:H73) | H4: =MAX(Timberäkning!K50:K73) | I4: =IF(F4>0,"DEFICIT","OK")
A5: 2024-01-04 | B5: =SUM(Timberäkning!B74:B97) | C5: =SUM(Timberäkning!C74:C97) | D5: =SUM(Timberäkning!D74:D97) | E5: =Parametrar!$B$4*24 | F5: =SUM(Timberäkning!G74:G97) | G5: =SUM(Timberäkning!H74:H97) | H5: =MAX(Timberäkning!K74:K97) | I5: =IF(F5>0,"DEFICIT","OK")
A6: 2024-01-05 | B6: =SUM(Timberäkning!B98:B121) | C6: =SUM(Timberäkning!C98:C121) | D6: =SUM(Timberäkning!D98:D121) | E6: =Parametrar!$B$4*24 | F6: =SUM(Timberäkning!G98:G121) | G6: =SUM(Timberäkning!H98:H121) | H6: =MAX(Timberäkning!K98:K121) | I6: =IF(F6>0,"DEFICIT","OK")
A7: 2024-01-06 | B7: =SUM(Timberäkning!B122:B145) | C7: =SUM(Timberäkning!C122:C145) | D7: =SUM(Timberäkning!D122:D145) | E7: =Parametrar!$B$4*24 | F7: =SUM(Timberäkning!G122:G145) | G7: =SUM(Timberäkning!H122:H145) | H7: =MAX(Timberäkning!K122:K145) | I7: =IF(F7>0,"DEFICIT","OK")
A8: 2024-01-07 | B8: =SUM(Timberäkning!B146:B169) | C8: =SUM(Timberäkning!C146:C169) | D8: =SUM(Timberäkning!D146:D169) | E8: =Parametrar!$B$4*24 | F8: =SUM(Timberäkning!G146:G169) | G8: =SUM(Timberäkning!H146:H169) | H8: =MAX(Timberäkning!K146:K169) | I8: =IF(F8>0,"DEFICIT","OK")
A9: 2024-01-08 | B9: =SUM(Timberäkning!B170:B193) | C9: =SUM(Timberäkning!C170:C193) | D9: =SUM(Timberäkning!D170:D193) | E9: =Parametrar!$B$4*24 | F9: =SUM(Timberäkning!G170:G193) | G9: =SUM(Timberäkning!H170:H193) | H9: =MAX(Timberäkning!K170:K193) | I9: =IF(F9>0,"DEFICIT","OK")
A10: 2024-01-09 | B10: =SUM(Timberäkning!B194:B217) | C10: =SUM(Timberäkning!C194:C217) | D10: =SUM(Timberäkning!D194:D217) | E10: =Parametrar!$B$4*24 | F10: =SUM(Timberäkning!G194:G217) | G10: =SUM(Timberäkning!H194:H217) | H10: =MAX(Timberäkning!K194:K217) | I10: =IF(F10>0,"DEFICIT","OK")
A11: 2024-01-10 | B11: =SUM(Timberäkning!B218:B241) | C11: =SUM(Timberäkning!C218:C241) | D11: =SUM(Timberäkning!D218:D241) | E11: =Parametrar!$B$4*24 | F11: =SUM(Timberäkning!G218:G241) | G11: =SUM(Timberäkning!H218:H241) | H11: =MAX(Timberäkning!K218:K241) | I11: =IF(F11>0,"DEFICIT","OK")
A12: 2024-01-11 | B12: =SUM(Timberäkning!B242:B265) | C12: =SUM(Timberäkning!C242:C265) | D12: =SUM(Timberäkning!D242:D265) | E12: =Parametrar!$B$4*24 | F12: =SUM(Timberäkning!G242:G265) | G12: =SUM(Timberäkning!H242:H265) | H12: =MAX(Timberäkning!K242:K265) | I12: =IF(F12>0,"DEFICIT","OK")
A13: 2024-01-12 | B13: =SUM(Timberäkning!B266:B289) | C13: =SUM(Timberäkning!C266:C289) | D13: =SUM(Timberäkning!D266:D289) | E13: =Parametrar!$B$4*24 | F13: =SUM(Timberäkning!G266:G289) | G13: =SUM(Timberäkning!H266:H289) | H13: =MAX(Timberäkning!K266:K289) | I13: =IF(F13>0,"DEFICIT","OK")
A14: 2024-01-13 | B14: =SUM(Timberäkning!B290:B313) | C14: =SUM(Timberäkning!C290:C313) | D14: =SUM(Timberäkning!D290:D313) | E14: =Parametrar!$B$4*24 | F14: =SUM(Timberäkning!G290:G313) | G14: =SUM(Timberäkning!H290:H313) | H14: =MAX(Timberäkning!K290:K313) | I14: =IF(F14>0,"DEFICIT","OK")
A15: 2024-01-14 | B15: =SUM(Timberäkning!B314:B337) | C15: =SUM(Timberäkning!C314:C337) | D15: =SUM(Timberäkning!D314:D337) | E15: =Parametrar!$B$4*24 | F15: =SUM(Timberäkning!G314:G337) | G15: =SUM(Timberäkning!H314:H337) | H15: =MAX(Timberäkning!K314:K337) | I15: =IF(F15>0,"DEFICIT","OK")
A16: 2024-01-15 | B16: =SUM(Timberäkning!B338:B361) | C16: =SUM(Timberäkning!C338:C361) | D16: =SUM(Timberäkning!D338:D361) | E16: =Parametrar!$B$4*24 | F16: =SUM(Timberäkning!G338:G361) | G16: =SUM(Timberäkning!H338:H361) | H16: =MAX(Timberäkning!K338:K361) | I16: =IF(F16>0,"DEFICIT","OK")
A17: 2024-01-16 | B17: =SUM(Timberäkning!B362:B385) | C17: =SUM(Timberäkning!C362:C385) | D17: =SUM(Timberäkning!D362:D385) | E17: =Parametrar!$B$4*24 | F17: =SUM(Timberäkning!G362:G385) | G17: =SUM(Timberäkning!H362:H385) | H17: =MAX(Timberäkning!K362:K385) | I17: =IF(F17>0,"DEFICIT","OK")
A18: 2024-01-17 | B18: =SUM(Timberäkning!B386:B409) | C18: =SUM(Timberäkning!C386:C409) | D18: =SUM(Timberäkning!D386:D409) | E18: =Parametrar!$B$4*24 | F18: =SUM(Timberäkning!G386:G409) | G18: =SUM(Timberäkning!H386:H409) | H18: =MAX(Timberäkning!K386:K409) | I18: =IF(F18>0,"DEFICIT","OK")
A19: 2024-01-18 | B19: =SUM(Timberäkning!B410:B433) | C19: =SUM(Timberäkning!C410:C433) | D19: =SUM(Timberäkning!D410:D433) | E19: =Parametrar!$B$4*24 | F19: =SUM(Timberäkning!G410:G433) | G19: =SUM(Timberäkning!H410:H433) | H19: =MAX(Timberäkning!K410:K433) | I19: =IF(F19>0,"DEFICIT","OK")
A20: 2024-01-19 | B20: =SUM(Timberäkning!B434:B457) | C20: =SUM(Timberäkning!C434:C457) | D20: =SUM(Timberäkning!D434:D457) | E20: =Parametrar!$B$4*24 | F20: =SUM(Timberäkning!G434:G457) | G20: =SUM(Timberäkning!H434:H457) | H20: =MAX(Timberäkning!K434:K457) | I20: =IF(F20>0,"DEFICIT","OK")
A21: 2024-01-20 | B21: =SUM(Timberäkning!B458:B481) | C21: =SUM(Timberäkning!C458:C481) | D21: =SUM(Timberäkning!D458:D481) | E21: =Parametrar!$B$4*24 | F21: =SUM(Timberäkning!G458:G481) | G21: =SUM(Timberäkning!H458:H481) | H21: =MAX(Timberäkning!K458:K481) | I21: =IF(F21>0,"DEFICIT","OK")
A22: 2024-01-21 | B22: =SUM(Timberäkning!B482:B505) | C22: =SUM(Timberäkning!C482:C505) | D22: =SUM(Timberäkning!D482:D505) | E22: =Parametrar!$B$4*24 | F22: =SUM(Timberäkning!G482:G505) | G22: =SUM(Timberäkning!H482:H505) | H22: =MAX(Timberäkning!K482:K505) | I22: =IF(F22>0,"DEFICIT","OK")
A23: 2024-01-22 | B23: =SUM(Timberäkning!B506:B529) | C23: =SUM(Timberäkning!C506:C529) | D23: =SUM(Timberäkning!D506:D529) | E23: =Parametrar!$B$4*24 | F23: =SUM(Timberäkning!G506:G529) | G23: =SUM(Timberäkning!H506:H529) | H23: =MAX(Timberäkning!K506:K529) | I23: =IF(F23>0,"DEFICIT","OK")
A24: 2024-01-23 | B24: =SUM(Timberäkning!B530:B553) | C24: =SUM(Timberäkning!C530:C553) | D24: =SUM(Timberäkning!D530:D553) | E24: =Parametrar!$B$4*24 | F24: =SUM(Timberäkning!G530:G553) | G24: =SUM(Timberäkning!H530:H553) | H24: =MAX(Timberäkning!K530:K553) | I24: =IF(F24>0,"DEFICIT","OK")
A25: 2024-01-24 | B25: =SUM(Timberäkning!B554:B577) | C25: =SUM(Timberäkning!C554:C577) | D25: =SUM(Timberäkning!D554:D577) | E25: =Parametrar!$B$4*24 | F25: =SUM(Timberäkning!G554:G577) | G25: =SUM(Timberäkning!H554:H577) | H25: =MAX(Timberäkning!K554:K577) | I25: =IF(F25>0,"DEFICIT","OK")
A26: 2024-01-25 | B26: =SUM(Timberäkning!B578:B601) | C26: =SUM(Timberäkning!C578:C601) | D26: =SUM(Timberäkning!D578:D601) | E26: =Parametrar!$B$4*24 | F26: =SUM(Timberäkning!G578:G601) | G26: =SUM(Timberäkning!H578:H601) | H26: =MAX(Timberäkning!K578:K601) | I26: =IF(F26>0,"DEFICIT","OK")
A27: 2024-01-26 | B27: =SUM(Timberäkning!B602:B625) | C27: =SUM(Timberäkning!C602:C625) | D27: =SUM(Timberäkning!D602:D625) | E27: =Parametrar!$B$4*24 | F27: =SUM(Timberäkning!G602:G625) | G27: =SUM(Timberäkning!H602:H625) | H27: =MAX(Timberäkning!K602:K625) | I27: =IF(F27>0,"DEFICIT","OK")
A28: 2024-01-27 | B28: =SUM(Timberäkning!B626:B649) | C28: =SUM(Timberäkning!C626:C649) | D28: =SUM(Timberäkning!D626:D649) | E28: =Parametrar!$B$4*24 | F28: =SUM(Timberäkning!G626:G649) | G28: =SUM(Timberäkning!H626:H649) | H28: =MAX(Timberäkning!K626:K649) | I28: =IF(F28>0,"DEFICIT","OK")
A29: 2024-01-28 | B29: =SUM(Timberäkning!B650:B673) | C29: =SUM(Timberäkning!C650:C673) | D29: =SUM(Timberäkning!D650:D673) | E29: =Parametrar!$B$4*24 | F29: =SUM(Timberäkning!G650:G673) | G29: =SUM(Timberäkning!H650:H673) | H29: =MAX(Timberäkning!K650:K673) | I29: =IF(F29>0,"DEFICIT","OK")
A30: 2024-01-29 | B30: =SUM(Timberäkning!B674:B697) | C30: =SUM(Timberäkning!C674:C697) | D30: =SUM(Timberäkning!D674:D697) | E30: =Parametrar!$B$4*24 | F30: =SUM(Timberäkning!G674:G697) | G30: =SUM(Timberäkning!H674:H697) | H30: =MAX(Timberäkning!K674:K697) | I30: =IF(F30>0,"DEFICIT","OK")
A31: 2024-01-30 | B31: =SUM(Timberäkning!B698:B721) | C31: =SUM(Timberäkning!C698:C721) | D31: =SUM(Timberäkning!D698:D721) | E31: =Parametrar!$B$4*24 | F31: =SUM(Timberäkning!G698:G721) | G31: =SUM(Timberäkning!H698:H721) | H31: =MAX(Timberäkning!K698:K721) | I31: =IF(F31>0,"DEFICIT","OK")
A32: 2024-01-31 | B32: =SUM(Timberäkning!B722:B745) | C32: =SUM(Timberäkning!C722:C745) | D32: =SUM(Timberäkning!D722:D745) | E32: =Parametrar!$B$4*24 | F32: =SUM(Timberäkning!G722:G745) | G32: =SUM(Timberäkning!H722:H745) | H32: =MAX(Timberäkning!K722:K745) | I32: =IF(F32>0,"DEFICIT","OK")
A33: 2024-02-01 | B33: =SUM(Timberäkning!B746:B769) | C33: =SUM(Timberäkning!C746:C769) | D33: =SUM(Timberäkning!D746:D769) | E33: =Parametrar!$B$4*24 | F33: =SUM(Timberäkning!G746:G769) | G33: =SUM(Timberäkning!H746:H769) | H33: =MAX(Timberäkning!K746:K769) | I33: =IF(F33>0,"DEFICIT","OK")
A34: 2024-02-02 | B34: =SUM(Timberäkning!B770:B793) | C34: =SUM(Timberäkning!C770:C793) | D34: =SUM(Timberäkning!D770:D793) | E34: =Parametrar!$B$4*24 | F34: =SUM(Timberäkning!G770:G793) | G34: =SUM(Timberäkning!H770:H793) | H34: =MAX(Timberäkning!K770:K793) | I34: =IF(F34>0,"DEFICIT","OK")
A35: 2024-02-03 | B35: =SUM(Timberäkning!B794:B817) | C35: =SUM(Timberäkning!C794:C817) | D35: =SUM(Timberäkning!D794:D817) | E35: =Parametrar!$B$4*24 | F35: =SUM(Timberäkning!G794:G817) | G35: =SUM(Timberäkning!H794:H817) | H35: =MAX(Timberäkning!K794:K817) | I35: =IF(F35>0,"DEFICIT","OK")
A36: 2024-02-04 | B36: =SUM(Timberäkning!B818:B841) | C36: =SUM(Timberäkning!C818:C841) | D36: =SUM(Timberäkning!D818:D841) | E36: =Parametrar!$B$4*24 | F36: =SUM(Timberäkning!G818:G841) | G36: =SUM(Timberäkning!H818:H841) | H36: =MAX(Timberäkning!K818:K841) | I36: =IF(F36>0,"DEFICIT","OK")
A37: 2024-02-05 | B37: =SUM(Timberäkning!B842:B865) | C37: =SUM(Timberäkning!C842:C865) | D37: =SUM(Timberäkning!D842:D865) | E37: =Parametrar!$B$4*24 | F37: =SUM(Timberäkning!G842:G865) | G37: =SUM(Timberäkning!H842:H865) | H37: =MAX(Timberäkning!K842:K865) | I37: =IF(F37>0,"DEFICIT","OK")
A38: 2024-02-06 | B38: =SUM(Timberäkning!B866:B889) | C38: =SUM(Timberäkning!C866:C889) | D38: =SUM(Timberäkning!D866:D889) | E38: =Parametrar!$B$4*24 | F38: =SUM(Timberäkning!G866:G889) | G38: =SUM(Timberäkning!H866:H889) | H38: =MAX(Timberäkning!K866:K889) | I38: =IF(F38>0,"DEFICIT","OK")
A39: 2024-02-07 | B39: =SUM(Timberäkning!B890:B913) | C39: =SUM(Timberäkning!C890:C913) | D39: =SUM(Timberäkning!D890:D913) | E39: =Parametrar!$B$4*24 | F39: =SUM(Timberäkning!G890:G913) | G39: =SUM(Timberäkning!H890:H913) | H39: =MAX(Timberäkning!K890:K913) | I39: =IF(F39>0,"DEFICIT","OK")
A40: 2024-02-08 | B40: =SUM(Timberäkning!B914:B937) | C40: =SUM(Timberäkning!C914:C937) | D40: =SUM(Timberäkning!D914:D937) | E40: =Parametrar!$B$4*24 | F40: =SUM(Timberäkning!G914:G937) | G40: =SUM(Timberäkning!H914:H937) | H40: =MAX(Timberäkning!K914:K937) | I40: =IF(F40>0,"DEFICIT","OK")
...

Sheet Kritiska Timmar
A1: Rank | B1: Timestamp | C1: Sol (MW) | D1: Vind (MW) | E1: Total (MW) | F1: Baseload (MW) | G1: Deficit (MW) | H1: Cum Sum
A2: 1 | B2: 2024-07-25 05:00 | C2: 0.0090708 | D2: 0.16751443 | E2: 0.17658523 | F2: 0.23147687 | G2: 0.054891632 | H2: 1293.5929
A3: 2 | B3: 2024-07-24 06:00 | C3: 0.0188616 | D3: 0.15828069 | E3: 0.17714229 | F3: 0.23147687 | G3: 0.054334575 | H3: 1293.6649
A4: 3 | B4: 2024-07-19 20:00 | C4: 0.0051548 | D4: 0.17426055 | E4: 0.17941535 | F4: 0.23147687 | G4: 0.052061518 | H4: 1286.3893
A5: 4 | B5: 2024-07-19 19:00 | C5: 0.0163492 | D5: 0.16591223 | E5: 0.18226143 | F5: 0.23147687 | G5: 0.049215434 | H5: 1286.4414
A6: 5 | B6: 2024-07-25 06:00 | C6: 0.0336748 | D6: 0.15005886 | E6: 0.18373366 | F6: 0.23147687 | G6: 0.047743201 | H6: 1293.5451
A7: 6 | B7: 2024-07-24 07:00 | C7: 0.0354584 | D7: 0.15069131 | E7: 0.18614971 | F7: 0.23147687 | G7: 0.045327153 | H7: 1293.6196
A8: 7 | B8: 2024-07-20 05:00 | C8: 0.0174204 | D8: 0.17025504 | E8: 0.18767544 | F8: 0.23147687 | G8: 0.043801423 | H8: 1286.3899
A9: 8 | B9: 2024-08-01 05:00 | C9: 0.0141648 | D9: 0.1739654 | E9: 0.1881302 | F9: 0.23147687 | G9: 0.043346661 | H9: 1314.2263
A10: 9 | B10: 2024-07-25 04:00 | C10: 0.003132 | D10: 0.18678302 | E10: 0.18991502 | F10: 0.23147687 | G10: 0.041561845 | H10: 1293.6478
A11: 10 | B11: 2024-08-01 19:00 | C11: 0.0084888 | D11: 0.18421107 | E11: 0.19269987 | F11: 0.23147687 | G11: 0.038777001 | H11: 1315.6219
A12: 11 | B12: 2024-06-27 06:00 | C12: 0.0182276 | D12: 0.17468218 | E12: 0.19290978 | F12: 0.23147687 | G12: 0.038567086 | H12: 1177.792
A13: 12 | B13: 2024-07-23 19:00 | C13: 0.0079916 | D13: 0.18530731 | E13: 0.19329891 | F13: 0.23147687 | G13: 0.038177957 | H13: 1293.9052
... A66: 65 | B66: 2024-05-19 18:00 | C66: 0.0256476 | D66: 0.20554565 | E66: 0.23119325 | F66: 0.23147687 | G66: 0.00028361632 | H66: 1001.523

Sheet Sammanfattning
A1: RESULTATSAMMANFATTNING
A3: NYCKELRESULTAT
A4: Total produktion | B4: =Parametrar!B16 | C4: MWh
A5: Baseload-behov | B5: =Parametrar!B17 | C5: MWh
A6: Leveransgrad | B6: =Parametrar!B16/Parametrar!B17 | C6: %
A8: Total deficit | B8: =Parametrar!B18 | C8: MWh
A9: Total surplus | B9: =Parametrar!B19 | C9: MWh
A10: Energibalans | B10: =Parametrar!B19*Parametrar!B5-Parametrar!B18 | C10: MWh
A12: Deficit-timmar | B12: =Parametrar!B20 | C12: st
A13: Surplus-timmar | B13: =Parametrar!B21 | C13: st
A15: Max deficit | B15: =Parametrar!B22 | C15: MW
A16: Max batteribehov | B16: =Parametrar!B23 | C16: MWh
A17: Batteriduration | B17: =Parametrar!B24 | C17: h
A20: FEASIBILITY
A21: Energibalans OK? | B21: =IF(B10>=0,"JA","NEJ - Omöjligt")
